[WARNING] RUNTIME_FRAMEWORK(8,7f60947a7740,python):2024-05-11-02:38:35.117.971 [mindspore/ccsrc/runtime/graph_scheduler/graph_scheduler.cc:2193] PersistDeviceTensor] Fetch no device tensor store by:Default/msrl-MSRL/learner-TD3Learner/critic_train-TrainOneStepCell/optimizer-Adam/data-8, type:1
ERROR:root:Exception while sending command.
Traceback (most recent call last):
  File "/usr/local/lib/python3.8/dist-packages/py4j/java_gateway.py", line 1224, in send_command
    raise Py4JNetworkError("Answer from Java side is empty")
py4j.protocol.Py4JNetworkError: Answer from Java side is empty

During handling of the above exception, another exception occurred:

Traceback (most recent call last):
  File "/usr/local/lib/python3.8/dist-packages/py4j/java_gateway.py", line 1038, in send_command
    response = connection.send_command(command)
  File "/usr/local/lib/python3.8/dist-packages/py4j/java_gateway.py", line 1228, in send_command
    raise Py4JNetworkError(
py4j.protocol.Py4JNetworkError: Error while receiving
ERROR:root:Exception while sending command.
Traceback (most recent call last):
  File "/usr/local/lib/python3.8/dist-packages/py4j/java_gateway.py", line 1224, in send_command
    raise Py4JNetworkError("Answer from Java side is empty")
py4j.protocol.Py4JNetworkError: Answer from Java side is empty

During handling of the above exception, another exception occurred:

Traceback (most recent call last):
  File "/usr/local/lib/python3.8/dist-packages/py4j/java_gateway.py", line 1038, in send_command
    response = connection.send_command(command)
  File "/usr/local/lib/python3.8/dist-packages/py4j/java_gateway.py", line 1228, in send_command
    raise Py4JNetworkError(
py4j.protocol.Py4JNetworkError: Error while receiving
ERROR:root:Exception while sending command.
Traceback (most recent call last):
  File "/usr/local/lib/python3.8/dist-packages/py4j/java_gateway.py", line 1224, in send_command
    raise Py4JNetworkError("Answer from Java side is empty")
py4j.protocol.Py4JNetworkError: Answer from Java side is empty

During handling of the above exception, another exception occurred:

Traceback (most recent call last):
  File "/usr/local/lib/python3.8/dist-packages/py4j/java_gateway.py", line 1038, in send_command
    response = connection.send_command(command)
  File "/usr/local/lib/python3.8/dist-packages/py4j/java_gateway.py", line 1228, in send_command
    raise Py4JNetworkError(
py4j.protocol.Py4JNetworkError: Error while receiving
ERROR:root:Exception while sending command.
Traceback (most recent call last):
  File "/usr/local/lib/python3.8/dist-packages/py4j/java_gateway.py", line 1224, in send_command
    raise Py4JNetworkError("Answer from Java side is empty")
py4j.protocol.Py4JNetworkError: Answer from Java side is empty

During handling of the above exception, another exception occurred:

Traceback (most recent call last):
  File "/usr/local/lib/python3.8/dist-packages/py4j/java_gateway.py", line 1038, in send_command
    response = connection.send_command(command)
  File "/usr/local/lib/python3.8/dist-packages/py4j/java_gateway.py", line 1228, in send_command
    raise Py4JNetworkError(
py4j.protocol.Py4JNetworkError: Error while receiving
ERROR:root:Exception while sending command.
Traceback (most recent call last):
  File "/usr/local/lib/python3.8/dist-packages/py4j/java_gateway.py", line 1224, in send_command
    raise Py4JNetworkError("Answer from Java side is empty")
py4j.protocol.Py4JNetworkError: Answer from Java side is empty

During handling of the above exception, another exception occurred:

Traceback (most recent call last):
  File "/usr/local/lib/python3.8/dist-packages/py4j/java_gateway.py", line 1038, in send_command
    response = connection.send_command(command)
  File "/usr/local/lib/python3.8/dist-packages/py4j/java_gateway.py", line 1228, in send_command
    raise Py4JNetworkError(
py4j.protocol.Py4JNetworkError: Error while receiving
ERROR:root:Exception while sending command.
Traceback (most recent call last):
  File "/usr/local/lib/python3.8/dist-packages/py4j/java_gateway.py", line 1224, in send_command
    raise Py4JNetworkError("Answer from Java side is empty")
py4j.protocol.Py4JNetworkError: Answer from Java side is empty

During handling of the above exception, another exception occurred:

Traceback (most recent call last):
  File "/usr/local/lib/python3.8/dist-packages/py4j/java_gateway.py", line 1038, in send_command
    response = connection.send_command(command)
  File "/usr/local/lib/python3.8/dist-packages/py4j/java_gateway.py", line 1228, in send_command
    raise Py4JNetworkError(
py4j.protocol.Py4JNetworkError: Error while receiving
ERROR:root:Exception while sending command.
Traceback (most recent call last):
  File "/usr/local/lib/python3.8/dist-packages/py4j/java_gateway.py", line 1224, in send_command
    raise Py4JNetworkError("Answer from Java side is empty")
py4j.protocol.Py4JNetworkError: Answer from Java side is empty

During handling of the above exception, another exception occurred:

Traceback (most recent call last):
  File "/usr/local/lib/python3.8/dist-packages/py4j/java_gateway.py", line 1038, in send_command
    response = connection.send_command(command)
  File "/usr/local/lib/python3.8/dist-packages/py4j/java_gateway.py", line 1228, in send_command
    raise Py4JNetworkError(
py4j.protocol.Py4JNetworkError: Error while receiving
ERROR:root:Exception while sending command.
Traceback (most recent call last):
  File "/usr/local/lib/python3.8/dist-packages/py4j/java_gateway.py", line 1224, in send_command
    raise Py4JNetworkError("Answer from Java side is empty")
py4j.protocol.Py4JNetworkError: Answer from Java side is empty

During handling of the above exception, another exception occurred:

Traceback (most recent call last):
  File "/usr/local/lib/python3.8/dist-packages/py4j/java_gateway.py", line 1038, in send_command
    response = connection.send_command(command)
  File "/usr/local/lib/python3.8/dist-packages/py4j/java_gateway.py", line 1228, in send_command
    raise Py4JNetworkError(
py4j.protocol.Py4JNetworkError: Error while receiving
ERROR:root:Exception while sending command.
Traceback (most recent call last):
  File "/usr/local/lib/python3.8/dist-packages/py4j/java_gateway.py", line 1224, in send_command
    raise Py4JNetworkError("Answer from Java side is empty")
py4j.protocol.Py4JNetworkError: Answer from Java side is empty

During handling of the above exception, another exception occurred:

Traceback (most recent call last):
  File "/usr/local/lib/python3.8/dist-packages/py4j/java_gateway.py", line 1038, in send_command
    response = connection.send_command(command)
  File "/usr/local/lib/python3.8/dist-packages/py4j/java_gateway.py", line 1228, in send_command
    raise Py4JNetworkError(
py4j.protocol.Py4JNetworkError: Error while receiving
ERROR:root:Exception while sending command.
Traceback (most recent call last):
  File "/usr/local/lib/python3.8/dist-packages/py4j/java_gateway.py", line 1224, in send_command
    raise Py4JNetworkError("Answer from Java side is empty")
py4j.protocol.Py4JNetworkError: Answer from Java side is empty

During handling of the above exception, another exception occurred:

Traceback (most recent call last):
  File "/usr/local/lib/python3.8/dist-packages/py4j/java_gateway.py", line 1038, in send_command
    response = connection.send_command(command)
  File "/usr/local/lib/python3.8/dist-packages/py4j/java_gateway.py", line 1228, in send_command
    raise Py4JNetworkError(
py4j.protocol.Py4JNetworkError: Error while receiving
ERROR:root:Exception while sending command.
Traceback (most recent call last):
  File "/usr/local/lib/python3.8/dist-packages/py4j/java_gateway.py", line 1224, in send_command
    raise Py4JNetworkError("Answer from Java side is empty")
py4j.protocol.Py4JNetworkError: Answer from Java side is empty

During handling of the above exception, another exception occurred:

Traceback (most recent call last):
  File "/usr/local/lib/python3.8/dist-packages/py4j/java_gateway.py", line 1038, in send_command
    response = connection.send_command(command)
  File "/usr/local/lib/python3.8/dist-packages/py4j/java_gateway.py", line 1228, in send_command
    raise Py4JNetworkError(
py4j.protocol.Py4JNetworkError: Error while receiving
ERROR:py4j.java_gateway:There was an exception while executing the Python Proxy on the Python Side.
Traceback (most recent call last):
  File "/usr/local/lib/python3.8/dist-packages/py4j/java_gateway.py", line 2463, in _call_proxy
    return_value = getattr(self.pool[obj_id], method)(*params)
  File "/app/myenv/gym_ai.py", line 111, in processing
    request = self.pipe.recv()
  File "/usr/lib/python3.8/multiprocessing/connection.py", line 250, in recv
    buf = self._recv_bytes()
  File "/usr/lib/python3.8/multiprocessing/connection.py", line 414, in _recv_bytes
    buf = self._recv(4)
  File "/usr/lib/python3.8/multiprocessing/connection.py", line 383, in _recv
    raise EOFError
EOFError
ERROR:root:Exception while sending command.
Traceback (most recent call last):
  File "/usr/local/lib/python3.8/dist-packages/py4j/java_gateway.py", line 1224, in send_command
    raise Py4JNetworkError("Answer from Java side is empty")
py4j.protocol.Py4JNetworkError: Answer from Java side is empty

During handling of the above exception, another exception occurred:

Traceback (most recent call last):
  File "/usr/local/lib/python3.8/dist-packages/py4j/java_gateway.py", line 1038, in send_command
    response = connection.send_command(command)
  File "/usr/local/lib/python3.8/dist-packages/py4j/java_gateway.py", line 1228, in send_command
    raise Py4JNetworkError(
py4j.protocol.Py4JNetworkError: Error while receiving
ERROR:root:Exception while sending command.
Traceback (most recent call last):
  File "/usr/local/lib/python3.8/dist-packages/py4j/java_gateway.py", line 1224, in send_command
    raise Py4JNetworkError("Answer from Java side is empty")
py4j.protocol.Py4JNetworkError: Answer from Java side is empty

During handling of the above exception, another exception occurred:

Traceback (most recent call last):
  File "/usr/local/lib/python3.8/dist-packages/py4j/java_gateway.py", line 1038, in send_command
    response = connection.send_command(command)
  File "/usr/local/lib/python3.8/dist-packages/py4j/java_gateway.py", line 1228, in send_command
    raise Py4JNetworkError(
py4j.protocol.Py4JNetworkError: Error while receiving
ERROR:root:Exception while sending command.
Traceback (most recent call last):
  File "/usr/local/lib/python3.8/dist-packages/py4j/java_gateway.py", line 1224, in send_command
    raise Py4JNetworkError("Answer from Java side is empty")
py4j.protocol.Py4JNetworkError: Answer from Java side is empty

During handling of the above exception, another exception occurred:

Traceback (most recent call last):
  File "/usr/local/lib/python3.8/dist-packages/py4j/java_gateway.py", line 1038, in send_command
    response = connection.send_command(command)
  File "/usr/local/lib/python3.8/dist-packages/py4j/java_gateway.py", line 1228, in send_command
    raise Py4JNetworkError(
py4j.protocol.Py4JNetworkError: Error while receiving
ERROR:root:Exception while sending command.
Traceback (most recent call last):
  File "/usr/local/lib/python3.8/dist-packages/py4j/java_gateway.py", line 1224, in send_command
    raise Py4JNetworkError("Answer from Java side is empty")
py4j.protocol.Py4JNetworkError: Answer from Java side is empty

During handling of the above exception, another exception occurred:

Traceback (most recent call last):
  File "/usr/local/lib/python3.8/dist-packages/py4j/java_gateway.py", line 1038, in send_command
    response = connection.send_command(command)
  File "/usr/local/lib/python3.8/dist-packages/py4j/java_gateway.py", line 1228, in send_command
    raise Py4JNetworkError(
py4j.protocol.Py4JNetworkError: Error while receiving
ERROR:root:Exception while sending command.
Traceback (most recent call last):
  File "/usr/local/lib/python3.8/dist-packages/py4j/java_gateway.py", line 1224, in send_command
    raise Py4JNetworkError("Answer from Java side is empty")
py4j.protocol.Py4JNetworkError: Answer from Java side is empty

During handling of the above exception, another exception occurred:

Traceback (most recent call last):
  File "/usr/local/lib/python3.8/dist-packages/py4j/java_gateway.py", line 1038, in send_command
    response = connection.send_command(command)
  File "/usr/local/lib/python3.8/dist-packages/py4j/java_gateway.py", line 1228, in send_command
    raise Py4JNetworkError(
py4j.protocol.Py4JNetworkError: Error while receiving
ERROR:root:Exception while sending command.
Traceback (most recent call last):
  File "/usr/local/lib/python3.8/dist-packages/py4j/java_gateway.py", line 1224, in send_command
    raise Py4JNetworkError("Answer from Java side is empty")
py4j.protocol.Py4JNetworkError: Answer from Java side is empty

During handling of the above exception, another exception occurred:

Traceback (most recent call last):
  File "/usr/local/lib/python3.8/dist-packages/py4j/java_gateway.py", line 1038, in send_command
    response = connection.send_command(command)
  File "/usr/local/lib/python3.8/dist-packages/py4j/java_gateway.py", line 1228, in send_command
    raise Py4JNetworkError(
py4j.protocol.Py4JNetworkError: Error while receiving
ERROR:root:Exception while sending command.
Traceback (most recent call last):
  File "/usr/local/lib/python3.8/dist-packages/py4j/java_gateway.py", line 1224, in send_command
    raise Py4JNetworkError("Answer from Java side is empty")
py4j.protocol.Py4JNetworkError: Answer from Java side is empty

During handling of the above exception, another exception occurred:

Traceback (most recent call last):
  File "/usr/local/lib/python3.8/dist-packages/py4j/java_gateway.py", line 1038, in send_command
    response = connection.send_command(command)
  File "/usr/local/lib/python3.8/dist-packages/py4j/java_gateway.py", line 1228, in send_command
    raise Py4JNetworkError(
py4j.protocol.Py4JNetworkError: Error while receiving
ERROR:root:Exception while sending command.
Traceback (most recent call last):
  File "/usr/local/lib/python3.8/dist-packages/py4j/java_gateway.py", line 1224, in send_command
    raise Py4JNetworkError("Answer from Java side is empty")
py4j.protocol.Py4JNetworkError: Answer from Java side is empty

During handling of the above exception, another exception occurred:

Traceback (most recent call last):
  File "/usr/local/lib/python3.8/dist-packages/py4j/java_gateway.py", line 1038, in send_command
    response = connection.send_command(command)
  File "/usr/local/lib/python3.8/dist-packages/py4j/java_gateway.py", line 1228, in send_command
    raise Py4JNetworkError(
py4j.protocol.Py4JNetworkError: Error while receiving
ERROR:root:Exception while sending command.
Traceback (most recent call last):
  File "/usr/local/lib/python3.8/dist-packages/py4j/java_gateway.py", line 1224, in send_command
    raise Py4JNetworkError("Answer from Java side is empty")
py4j.protocol.Py4JNetworkError: Answer from Java side is empty

During handling of the above exception, another exception occurred:

Traceback (most recent call last):
  File "/usr/local/lib/python3.8/dist-packages/py4j/java_gateway.py", line 1038, in send_command
    response = connection.send_command(command)
  File "/usr/local/lib/python3.8/dist-packages/py4j/java_gateway.py", line 1228, in send_command
    raise Py4JNetworkError(
py4j.protocol.Py4JNetworkError: Error while receiving
ERROR:root:Exception while sending command.
Traceback (most recent call last):
  File "/usr/local/lib/python3.8/dist-packages/py4j/java_gateway.py", line 1224, in send_command
    raise Py4JNetworkError("Answer from Java side is empty")
py4j.protocol.Py4JNetworkError: Answer from Java side is empty

During handling of the above exception, another exception occurred:

Traceback (most recent call last):
  File "/usr/local/lib/python3.8/dist-packages/py4j/java_gateway.py", line 1038, in send_command
    response = connection.send_command(command)
  File "/usr/local/lib/python3.8/dist-packages/py4j/java_gateway.py", line 1228, in send_command
    raise Py4JNetworkError(
py4j.protocol.Py4JNetworkError: Error while receiving
ERROR:root:Exception while sending command.
Traceback (most recent call last):
  File "/usr/local/lib/python3.8/dist-packages/py4j/java_gateway.py", line 1224, in send_command
    raise Py4JNetworkError("Answer from Java side is empty")
py4j.protocol.Py4JNetworkError: Answer from Java side is empty

During handling of the above exception, another exception occurred:

Traceback (most recent call last):
  File "/usr/local/lib/python3.8/dist-packages/py4j/java_gateway.py", line 1038, in send_command
    response = connection.send_command(command)
  File "/usr/local/lib/python3.8/dist-packages/py4j/java_gateway.py", line 1228, in send_command
    raise Py4JNetworkError(
py4j.protocol.Py4JNetworkError: Error while receiving
ERROR:root:Exception while sending command.
Traceback (most recent call last):
  File "/usr/local/lib/python3.8/dist-packages/py4j/java_gateway.py", line 1224, in send_command
    raise Py4JNetworkError("Answer from Java side is empty")
py4j.protocol.Py4JNetworkError: Answer from Java side is empty

During handling of the above exception, another exception occurred:

Traceback (most recent call last):
  File "/usr/local/lib/python3.8/dist-packages/py4j/java_gateway.py", line 1038, in send_command
    response = connection.send_command(command)
  File "/usr/local/lib/python3.8/dist-packages/py4j/java_gateway.py", line 1228, in send_command
    raise Py4JNetworkError(
py4j.protocol.Py4JNetworkError: Error while receiving
ERROR:root:Exception while sending command.
Traceback (most recent call last):
  File "/usr/local/lib/python3.8/dist-packages/py4j/java_gateway.py", line 1224, in send_command
    raise Py4JNetworkError("Answer from Java side is empty")
py4j.protocol.Py4JNetworkError: Answer from Java side is empty

During handling of the above exception, another exception occurred:

Traceback (most recent call last):
  File "/usr/local/lib/python3.8/dist-packages/py4j/java_gateway.py", line 1038, in send_command
    response = connection.send_command(command)
  File "/usr/local/lib/python3.8/dist-packages/py4j/java_gateway.py", line 1228, in send_command
    raise Py4JNetworkError(
py4j.protocol.Py4JNetworkError: Error while receiving
ERROR:root:Exception while sending command.
Traceback (most recent call last):
  File "/usr/local/lib/python3.8/dist-packages/py4j/java_gateway.py", line 1224, in send_command
    raise Py4JNetworkError("Answer from Java side is empty")
py4j.protocol.Py4JNetworkError: Answer from Java side is empty

During handling of the above exception, another exception occurred:

Traceback (most recent call last):
  File "/usr/local/lib/python3.8/dist-packages/py4j/java_gateway.py", line 1038, in send_command
    response = connection.send_command(command)
  File "/usr/local/lib/python3.8/dist-packages/py4j/java_gateway.py", line 1228, in send_command
    raise Py4JNetworkError(
py4j.protocol.Py4JNetworkError: Error while receiving
ERROR:root:Exception while sending command.
Traceback (most recent call last):
  File "/usr/local/lib/python3.8/dist-packages/py4j/java_gateway.py", line 1224, in send_command
    raise Py4JNetworkError("Answer from Java side is empty")
py4j.protocol.Py4JNetworkError: Answer from Java side is empty

During handling of the above exception, another exception occurred:

Traceback (most recent call last):
  File "/usr/local/lib/python3.8/dist-packages/py4j/java_gateway.py", line 1038, in send_command
    response = connection.send_command(command)
  File "/usr/local/lib/python3.8/dist-packages/py4j/java_gateway.py", line 1228, in send_command
    raise Py4JNetworkError(
py4j.protocol.Py4JNetworkError: Error while receiving
ERROR:py4j.java_gateway:There was an exception while executing the Python Proxy on the Python Side.
Traceback (most recent call last):
  File "/usr/local/lib/python3.8/dist-packages/py4j/java_gateway.py", line 2463, in _call_proxy
    return_value = getattr(self.pool[obj_id], method)(*params)
  File "/app/myenv/gym_ai.py", line 111, in processing
    request = self.pipe.recv()
  File "/usr/lib/python3.8/multiprocessing/connection.py", line 250, in recv
    buf = self._recv_bytes()
  File "/usr/lib/python3.8/multiprocessing/connection.py", line 414, in _recv_bytes
    buf = self._recv(4)
  File "/usr/lib/python3.8/multiprocessing/connection.py", line 383, in _recv
    raise EOFError
EOFError
ERROR:root:Exception while sending command.
Traceback (most recent call last):
  File "/usr/local/lib/python3.8/dist-packages/py4j/java_gateway.py", line 1224, in send_command
    raise Py4JNetworkError("Answer from Java side is empty")
py4j.protocol.Py4JNetworkError: Answer from Java side is empty

During handling of the above exception, another exception occurred:

Traceback (most recent call last):
  File "/usr/local/lib/python3.8/dist-packages/py4j/java_gateway.py", line 1038, in send_command
    response = connection.send_command(command)
  File "/usr/local/lib/python3.8/dist-packages/py4j/java_gateway.py", line 1228, in send_command
    raise Py4JNetworkError(
py4j.protocol.Py4JNetworkError: Error while receiving
ERROR:root:Exception while sending command.
Traceback (most recent call last):
  File "/usr/local/lib/python3.8/dist-packages/py4j/java_gateway.py", line 1224, in send_command
    raise Py4JNetworkError("Answer from Java side is empty")
py4j.protocol.Py4JNetworkError: Answer from Java side is empty

During handling of the above exception, another exception occurred:

Traceback (most recent call last):
  File "/usr/local/lib/python3.8/dist-packages/py4j/java_gateway.py", line 1038, in send_command
    response = connection.send_command(command)
  File "/usr/local/lib/python3.8/dist-packages/py4j/java_gateway.py", line 1228, in send_command
    raise Py4JNetworkError(
py4j.protocol.Py4JNetworkError: Error while receiving
ERROR:root:Exception while sending command.
Traceback (most recent call last):
  File "/usr/local/lib/python3.8/dist-packages/py4j/java_gateway.py", line 1224, in send_command
    raise Py4JNetworkError("Answer from Java side is empty")
py4j.protocol.Py4JNetworkError: Answer from Java side is empty

During handling of the above exception, another exception occurred:

Traceback (most recent call last):
  File "/usr/local/lib/python3.8/dist-packages/py4j/java_gateway.py", line 1038, in send_command
    response = connection.send_command(command)
  File "/usr/local/lib/python3.8/dist-packages/py4j/java_gateway.py", line 1228, in send_command
    raise Py4JNetworkError(
py4j.protocol.Py4JNetworkError: Error while receiving
ERROR:root:Exception while sending command.
Traceback (most recent call last):
  File "/usr/local/lib/python3.8/dist-packages/py4j/java_gateway.py", line 1224, in send_command
    raise Py4JNetworkError("Answer from Java side is empty")
py4j.protocol.Py4JNetworkError: Answer from Java side is empty

During handling of the above exception, another exception occurred:

Traceback (most recent call last):
  File "/usr/local/lib/python3.8/dist-packages/py4j/java_gateway.py", line 1038, in send_command
    response = connection.send_command(command)
  File "/usr/local/lib/python3.8/dist-packages/py4j/java_gateway.py", line 1228, in send_command
    raise Py4JNetworkError(
py4j.protocol.Py4JNetworkError: Error while receiving
ERROR:root:Exception while sending command.
Traceback (most recent call last):
  File "/usr/local/lib/python3.8/dist-packages/py4j/java_gateway.py", line 1224, in send_command
    raise Py4JNetworkError("Answer from Java side is empty")
py4j.protocol.Py4JNetworkError: Answer from Java side is empty

During handling of the above exception, another exception occurred:

Traceback (most recent call last):
  File "/usr/local/lib/python3.8/dist-packages/py4j/java_gateway.py", line 1038, in send_command
    response = connection.send_command(command)
  File "/usr/local/lib/python3.8/dist-packages/py4j/java_gateway.py", line 1228, in send_command
    raise Py4JNetworkError(
py4j.protocol.Py4JNetworkError: Error while receiving
ERROR:root:Exception while sending command.
Traceback (most recent call last):
  File "/usr/local/lib/python3.8/dist-packages/py4j/java_gateway.py", line 1224, in send_command
    raise Py4JNetworkError("Answer from Java side is empty")
py4j.protocol.Py4JNetworkError: Answer from Java side is empty

During handling of the above exception, another exception occurred:

Traceback (most recent call last):
  File "/usr/local/lib/python3.8/dist-packages/py4j/java_gateway.py", line 1038, in send_command
    response = connection.send_command(command)
  File "/usr/local/lib/python3.8/dist-packages/py4j/java_gateway.py", line 1228, in send_command
    raise Py4JNetworkError(
py4j.protocol.Py4JNetworkError: Error while receiving
ERROR:root:Exception while sending command.
Traceback (most recent call last):
  File "/usr/local/lib/python3.8/dist-packages/py4j/java_gateway.py", line 1224, in send_command
    raise Py4JNetworkError("Answer from Java side is empty")
py4j.protocol.Py4JNetworkError: Answer from Java side is empty

During handling of the above exception, another exception occurred:

Traceback (most recent call last):
  File "/usr/local/lib/python3.8/dist-packages/py4j/java_gateway.py", line 1038, in send_command
    response = connection.send_command(command)
  File "/usr/local/lib/python3.8/dist-packages/py4j/java_gateway.py", line 1228, in send_command
    raise Py4JNetworkError(
py4j.protocol.Py4JNetworkError: Error while receiving
ERROR:root:Exception while sending command.
Traceback (most recent call last):
  File "/usr/local/lib/python3.8/dist-packages/py4j/java_gateway.py", line 1224, in send_command
    raise Py4JNetworkError("Answer from Java side is empty")
py4j.protocol.Py4JNetworkError: Answer from Java side is empty

During handling of the above exception, another exception occurred:

Traceback (most recent call last):
  File "/usr/local/lib/python3.8/dist-packages/py4j/java_gateway.py", line 1038, in send_command
    response = connection.send_command(command)
  File "/usr/local/lib/python3.8/dist-packages/py4j/java_gateway.py", line 1228, in send_command
    raise Py4JNetworkError(
py4j.protocol.Py4JNetworkError: Error while receiving
ERROR:root:Exception while sending command.
Traceback (most recent call last):
  File "/usr/local/lib/python3.8/dist-packages/py4j/java_gateway.py", line 1224, in send_command
    raise Py4JNetworkError("Answer from Java side is empty")
py4j.protocol.Py4JNetworkError: Answer from Java side is empty

During handling of the above exception, another exception occurred:

Traceback (most recent call last):
  File "/usr/local/lib/python3.8/dist-packages/py4j/java_gateway.py", line 1038, in send_command
    response = connection.send_command(command)
  File "/usr/local/lib/python3.8/dist-packages/py4j/java_gateway.py", line 1228, in send_command
    raise Py4JNetworkError(
py4j.protocol.Py4JNetworkError: Error while receiving
ERROR:root:Exception while sending command.
Traceback (most recent call last):
  File "/usr/local/lib/python3.8/dist-packages/py4j/java_gateway.py", line 1224, in send_command
    raise Py4JNetworkError("Answer from Java side is empty")
py4j.protocol.Py4JNetworkError: Answer from Java side is empty

During handling of the above exception, another exception occurred:

Traceback (most recent call last):
  File "/usr/local/lib/python3.8/dist-packages/py4j/java_gateway.py", line 1038, in send_command
    response = connection.send_command(command)
  File "/usr/local/lib/python3.8/dist-packages/py4j/java_gateway.py", line 1228, in send_command
    raise Py4JNetworkError(
py4j.protocol.Py4JNetworkError: Error while receiving
ERROR:root:Exception while sending command.
Traceback (most recent call last):
  File "/usr/local/lib/python3.8/dist-packages/py4j/java_gateway.py", line 1224, in send_command
    raise Py4JNetworkError("Answer from Java side is empty")
py4j.protocol.Py4JNetworkError: Answer from Java side is empty

During handling of the above exception, another exception occurred:

Traceback (most recent call last):
  File "/usr/local/lib/python3.8/dist-packages/py4j/java_gateway.py", line 1038, in send_command
    response = connection.send_command(command)
  File "/usr/local/lib/python3.8/dist-packages/py4j/java_gateway.py", line 1228, in send_command
    raise Py4JNetworkError(
py4j.protocol.Py4JNetworkError: Error while receiving
ERROR:root:Exception while sending command.
Traceback (most recent call last):
  File "/usr/local/lib/python3.8/dist-packages/py4j/java_gateway.py", line 1224, in send_command
    raise Py4JNetworkError("Answer from Java side is empty")
py4j.protocol.Py4JNetworkError: Answer from Java side is empty

During handling of the above exception, another exception occurred:

Traceback (most recent call last):
  File "/usr/local/lib/python3.8/dist-packages/py4j/java_gateway.py", line 1038, in send_command
    response = connection.send_command(command)
  File "/usr/local/lib/python3.8/dist-packages/py4j/java_gateway.py", line 1228, in send_command
    raise Py4JNetworkError(
py4j.protocol.Py4JNetworkError: Error while receiving
ERROR:py4j.java_gateway:There was an exception while executing the Python Proxy on the Python Side.
Traceback (most recent call last):
  File "/usr/local/lib/python3.8/dist-packages/py4j/java_gateway.py", line 2463, in _call_proxy
    return_value = getattr(self.pool[obj_id], method)(*params)
  File "/app/myenv/gym_ai.py", line 111, in processing
    request = self.pipe.recv()
  File "/usr/lib/python3.8/multiprocessing/connection.py", line 250, in recv
    buf = self._recv_bytes()
  File "/usr/lib/python3.8/multiprocessing/connection.py", line 414, in _recv_bytes
    buf = self._recv(4)
  File "/usr/lib/python3.8/multiprocessing/connection.py", line 383, in _recv
    raise EOFError
EOFError
ERROR:root:Exception while sending command.
Traceback (most recent call last):
  File "/usr/local/lib/python3.8/dist-packages/py4j/java_gateway.py", line 1224, in send_command
    raise Py4JNetworkError("Answer from Java side is empty")
py4j.protocol.Py4JNetworkError: Answer from Java side is empty

During handling of the above exception, another exception occurred:

Traceback (most recent call last):
  File "/usr/local/lib/python3.8/dist-packages/py4j/java_gateway.py", line 1038, in send_command
    response = connection.send_command(command)
  File "/usr/local/lib/python3.8/dist-packages/py4j/java_gateway.py", line 1228, in send_command
    raise Py4JNetworkError(
py4j.protocol.Py4JNetworkError: Error while receiving
ERROR:root:Exception while sending command.
Traceback (most recent call last):
  File "/usr/local/lib/python3.8/dist-packages/py4j/java_gateway.py", line 1224, in send_command
    raise Py4JNetworkError("Answer from Java side is empty")
py4j.protocol.Py4JNetworkError: Answer from Java side is empty

During handling of the above exception, another exception occurred:

Traceback (most recent call last):
  File "/usr/local/lib/python3.8/dist-packages/py4j/java_gateway.py", line 1038, in send_command
    response = connection.send_command(command)
  File "/usr/local/lib/python3.8/dist-packages/py4j/java_gateway.py", line 1228, in send_command
    raise Py4JNetworkError(
py4j.protocol.Py4JNetworkError: Error while receiving
ERROR:root:Exception while sending command.
Traceback (most recent call last):
  File "/usr/local/lib/python3.8/dist-packages/py4j/java_gateway.py", line 1224, in send_command
    raise Py4JNetworkError("Answer from Java side is empty")
py4j.protocol.Py4JNetworkError: Answer from Java side is empty

During handling of the above exception, another exception occurred:

Traceback (most recent call last):
  File "/usr/local/lib/python3.8/dist-packages/py4j/java_gateway.py", line 1038, in send_command
    response = connection.send_command(command)
  File "/usr/local/lib/python3.8/dist-packages/py4j/java_gateway.py", line 1228, in send_command
    raise Py4JNetworkError(
py4j.protocol.Py4JNetworkError: Error while receiving
ERROR:root:Exception while sending command.
Traceback (most recent call last):
  File "/usr/local/lib/python3.8/dist-packages/py4j/java_gateway.py", line 1224, in send_command
    raise Py4JNetworkError("Answer from Java side is empty")
py4j.protocol.Py4JNetworkError: Answer from Java side is empty

During handling of the above exception, another exception occurred:

Traceback (most recent call last):
  File "/usr/local/lib/python3.8/dist-packages/py4j/java_gateway.py", line 1038, in send_command
    response = connection.send_command(command)
  File "/usr/local/lib/python3.8/dist-packages/py4j/java_gateway.py", line 1228, in send_command
    raise Py4JNetworkError(
py4j.protocol.Py4JNetworkError: Error while receiving
ERROR:root:Exception while sending command.
Traceback (most recent call last):
  File "/usr/local/lib/python3.8/dist-packages/py4j/java_gateway.py", line 1224, in send_command
    raise Py4JNetworkError("Answer from Java side is empty")
py4j.protocol.Py4JNetworkError: Answer from Java side is empty

During handling of the above exception, another exception occurred:

Traceback (most recent call last):
  File "/usr/local/lib/python3.8/dist-packages/py4j/java_gateway.py", line 1038, in send_command
    response = connection.send_command(command)
  File "/usr/local/lib/python3.8/dist-packages/py4j/java_gateway.py", line 1228, in send_command
    raise Py4JNetworkError(
py4j.protocol.Py4JNetworkError: Error while receiving
ERROR:root:Exception while sending command.
Traceback (most recent call last):
  File "/usr/local/lib/python3.8/dist-packages/py4j/java_gateway.py", line 1224, in send_command
    raise Py4JNetworkError("Answer from Java side is empty")
py4j.protocol.Py4JNetworkError: Answer from Java side is empty

During handling of the above exception, another exception occurred:

Traceback (most recent call last):
  File "/usr/local/lib/python3.8/dist-packages/py4j/java_gateway.py", line 1038, in send_command
    response = connection.send_command(command)
  File "/usr/local/lib/python3.8/dist-packages/py4j/java_gateway.py", line 1228, in send_command
    raise Py4JNetworkError(
py4j.protocol.Py4JNetworkError: Error while receiving
ERROR:root:Exception while sending command.
Traceback (most recent call last):
  File "/usr/local/lib/python3.8/dist-packages/py4j/java_gateway.py", line 1224, in send_command
    raise Py4JNetworkError("Answer from Java side is empty")
py4j.protocol.Py4JNetworkError: Answer from Java side is empty

During handling of the above exception, another exception occurred:

Traceback (most recent call last):
  File "/usr/local/lib/python3.8/dist-packages/py4j/java_gateway.py", line 1038, in send_command
    response = connection.send_command(command)
  File "/usr/local/lib/python3.8/dist-packages/py4j/java_gateway.py", line 1228, in send_command
    raise Py4JNetworkError(
py4j.protocol.Py4JNetworkError: Error while receiving
ERROR:root:Exception while sending command.
Traceback (most recent call last):
  File "/usr/local/lib/python3.8/dist-packages/py4j/java_gateway.py", line 1224, in send_command
    raise Py4JNetworkError("Answer from Java side is empty")
py4j.protocol.Py4JNetworkError: Answer from Java side is empty

During handling of the above exception, another exception occurred:

Traceback (most recent call last):
  File "/usr/local/lib/python3.8/dist-packages/py4j/java_gateway.py", line 1038, in send_command
    response = connection.send_command(command)
  File "/usr/local/lib/python3.8/dist-packages/py4j/java_gateway.py", line 1228, in send_command
    raise Py4JNetworkError(
py4j.protocol.Py4JNetworkError: Error while receiving
ERROR:root:Exception while sending command.
Traceback (most recent call last):
  File "/usr/local/lib/python3.8/dist-packages/py4j/java_gateway.py", line 1224, in send_command
    raise Py4JNetworkError("Answer from Java side is empty")
py4j.protocol.Py4JNetworkError: Answer from Java side is empty

During handling of the above exception, another exception occurred:

Traceback (most recent call last):
  File "/usr/local/lib/python3.8/dist-packages/py4j/java_gateway.py", line 1038, in send_command
    response = connection.send_command(command)
  File "/usr/local/lib/python3.8/dist-packages/py4j/java_gateway.py", line 1228, in send_command
    raise Py4JNetworkError(
py4j.protocol.Py4JNetworkError: Error while receiving
ERROR:root:Exception while sending command.
Traceback (most recent call last):
  File "/usr/local/lib/python3.8/dist-packages/py4j/java_gateway.py", line 1224, in send_command
    raise Py4JNetworkError("Answer from Java side is empty")
py4j.protocol.Py4JNetworkError: Answer from Java side is empty

During handling of the above exception, another exception occurred:

Traceback (most recent call last):
  File "/usr/local/lib/python3.8/dist-packages/py4j/java_gateway.py", line 1038, in send_command
    response = connection.send_command(command)
  File "/usr/local/lib/python3.8/dist-packages/py4j/java_gateway.py", line 1228, in send_command
    raise Py4JNetworkError(
py4j.protocol.Py4JNetworkError: Error while receiving
ERROR:root:Exception while sending command.
Traceback (most recent call last):
  File "/usr/local/lib/python3.8/dist-packages/py4j/java_gateway.py", line 1224, in send_command
    raise Py4JNetworkError("Answer from Java side is empty")
py4j.protocol.Py4JNetworkError: Answer from Java side is empty

During handling of the above exception, another exception occurred:

Traceback (most recent call last):
  File "/usr/local/lib/python3.8/dist-packages/py4j/java_gateway.py", line 1038, in send_command
    response = connection.send_command(command)
  File "/usr/local/lib/python3.8/dist-packages/py4j/java_gateway.py", line 1228, in send_command
    raise Py4JNetworkError(
py4j.protocol.Py4JNetworkError: Error while receiving
ERROR:root:Exception while sending command.
Traceback (most recent call last):
  File "/usr/local/lib/python3.8/dist-packages/py4j/java_gateway.py", line 1224, in send_command
    raise Py4JNetworkError("Answer from Java side is empty")
py4j.protocol.Py4JNetworkError: Answer from Java side is empty

During handling of the above exception, another exception occurred:

Traceback (most recent call last):
  File "/usr/local/lib/python3.8/dist-packages/py4j/java_gateway.py", line 1038, in send_command
    response = connection.send_command(command)
  File "/usr/local/lib/python3.8/dist-packages/py4j/java_gateway.py", line 1228, in send_command
    raise Py4JNetworkError(
py4j.protocol.Py4JNetworkError: Error while receiving
ERROR:root:Exception while sending command.
Traceback (most recent call last):
  File "/usr/local/lib/python3.8/dist-packages/py4j/java_gateway.py", line 1224, in send_command
    raise Py4JNetworkError("Answer from Java side is empty")
py4j.protocol.Py4JNetworkError: Answer from Java side is empty

During handling of the above exception, another exception occurred:

Traceback (most recent call last):
  File "/usr/local/lib/python3.8/dist-packages/py4j/java_gateway.py", line 1038, in send_command
    response = connection.send_command(command)
  File "/usr/local/lib/python3.8/dist-packages/py4j/java_gateway.py", line 1228, in send_command
    raise Py4JNetworkError(
py4j.protocol.Py4JNetworkError: Error while receiving
ERROR:root:Exception while sending command.
Traceback (most recent call last):
  File "/usr/local/lib/python3.8/dist-packages/py4j/java_gateway.py", line 1224, in send_command
    raise Py4JNetworkError("Answer from Java side is empty")
py4j.protocol.Py4JNetworkError: Answer from Java side is empty

During handling of the above exception, another exception occurred:

Traceback (most recent call last):
  File "/usr/local/lib/python3.8/dist-packages/py4j/java_gateway.py", line 1038, in send_command
    response = connection.send_command(command)
  File "/usr/local/lib/python3.8/dist-packages/py4j/java_gateway.py", line 1228, in send_command
    raise Py4JNetworkError(
py4j.protocol.Py4JNetworkError: Error while receiving
ERROR:root:Exception while sending command.
Traceback (most recent call last):
  File "/usr/local/lib/python3.8/dist-packages/py4j/java_gateway.py", line 1224, in send_command
    raise Py4JNetworkError("Answer from Java side is empty")
py4j.protocol.Py4JNetworkError: Answer from Java side is empty

During handling of the above exception, another exception occurred:

Traceback (most recent call last):
  File "/usr/local/lib/python3.8/dist-packages/py4j/java_gateway.py", line 1038, in send_command
    response = connection.send_command(command)
  File "/usr/local/lib/python3.8/dist-packages/py4j/java_gateway.py", line 1228, in send_command
    raise Py4JNetworkError(
py4j.protocol.Py4JNetworkError: Error while receiving
ERROR:root:Exception while sending command.
Traceback (most recent call last):
  File "/usr/local/lib/python3.8/dist-packages/py4j/java_gateway.py", line 1224, in send_command
    raise Py4JNetworkError("Answer from Java side is empty")
py4j.protocol.Py4JNetworkError: Answer from Java side is empty

During handling of the above exception, another exception occurred:

Traceback (most recent call last):
  File "/usr/local/lib/python3.8/dist-packages/py4j/java_gateway.py", line 1038, in send_command
    response = connection.send_command(command)
  File "/usr/local/lib/python3.8/dist-packages/py4j/java_gateway.py", line 1228, in send_command
    raise Py4JNetworkError(
py4j.protocol.Py4JNetworkError: Error while receiving
ERROR:py4j.java_gateway:There was an exception while executing the Python Proxy on the Python Side.
Traceback (most recent call last):
  File "/usr/local/lib/python3.8/dist-packages/py4j/java_gateway.py", line 2463, in _call_proxy
    return_value = getattr(self.pool[obj_id], method)(*params)
  File "/app/myenv/gym_ai.py", line 111, in processing
    request = self.pipe.recv()
  File "/usr/lib/python3.8/multiprocessing/connection.py", line 250, in recv
    buf = self._recv_bytes()
  File "/usr/lib/python3.8/multiprocessing/connection.py", line 414, in _recv_bytes
    buf = self._recv(4)
  File "/usr/lib/python3.8/multiprocessing/connection.py", line 383, in _recv
    raise EOFError
EOFError
ERROR:root:Exception while sending command.
Traceback (most recent call last):
  File "/usr/local/lib/python3.8/dist-packages/py4j/java_gateway.py", line 1224, in send_command
    raise Py4JNetworkError("Answer from Java side is empty")
py4j.protocol.Py4JNetworkError: Answer from Java side is empty

During handling of the above exception, another exception occurred:

Traceback (most recent call last):
  File "/usr/local/lib/python3.8/dist-packages/py4j/java_gateway.py", line 1038, in send_command
    response = connection.send_command(command)
  File "/usr/local/lib/python3.8/dist-packages/py4j/java_gateway.py", line 1228, in send_command
    raise Py4JNetworkError(
py4j.protocol.Py4JNetworkError: Error while receiving
ERROR:py4j.java_gateway:There was an exception while executing the Python Proxy on the Python Side.
Traceback (most recent call last):
  File "/usr/local/lib/python3.8/dist-packages/py4j/java_gateway.py", line 2463, in _call_proxy
    return_value = getattr(self.pool[obj_id], method)(*params)
  File "/app/myenv/gym_ai.py", line 111, in processing
    request = self.pipe.recv()
  File "/usr/lib/python3.8/multiprocessing/connection.py", line 250, in recv
    buf = self._recv_bytes()
  File "/usr/lib/python3.8/multiprocessing/connection.py", line 414, in _recv_bytes
    buf = self._recv(4)
  File "/usr/lib/python3.8/multiprocessing/connection.py", line 383, in _recv
    raise EOFError
EOFError
ERROR:root:Exception while sending command.
Traceback (most recent call last):
  File "/usr/local/lib/python3.8/dist-packages/py4j/java_gateway.py", line 1224, in send_command
    raise Py4JNetworkError("Answer from Java side is empty")
py4j.protocol.Py4JNetworkError: Answer from Java side is empty

During handling of the above exception, another exception occurred:

Traceback (most recent call last):
  File "/usr/local/lib/python3.8/dist-packages/py4j/java_gateway.py", line 1038, in send_command
    response = connection.send_command(command)
  File "/usr/local/lib/python3.8/dist-packages/py4j/java_gateway.py", line 1228, in send_command
    raise Py4JNetworkError(
py4j.protocol.Py4JNetworkError: Error while receiving
ERROR:root:Exception while sending command.
Traceback (most recent call last):
  File "/usr/local/lib/python3.8/dist-packages/py4j/java_gateway.py", line 1224, in send_command
    raise Py4JNetworkError("Answer from Java side is empty")
py4j.protocol.Py4JNetworkError: Answer from Java side is empty

During handling of the above exception, another exception occurred:

Traceback (most recent call last):
  File "/usr/local/lib/python3.8/dist-packages/py4j/java_gateway.py", line 1038, in send_command
    response = connection.send_command(command)
  File "/usr/local/lib/python3.8/dist-packages/py4j/java_gateway.py", line 1228, in send_command
    raise Py4JNetworkError(
py4j.protocol.Py4JNetworkError: Error while receiving
ERROR:root:Exception while sending command.
Traceback (most recent call last):
  File "/usr/local/lib/python3.8/dist-packages/py4j/java_gateway.py", line 1224, in send_command
    raise Py4JNetworkError("Answer from Java side is empty")
py4j.protocol.Py4JNetworkError: Answer from Java side is empty

During handling of the above exception, another exception occurred:

Traceback (most recent call last):
  File "/usr/local/lib/python3.8/dist-packages/py4j/java_gateway.py", line 1038, in send_command
    response = connection.send_command(command)
  File "/usr/local/lib/python3.8/dist-packages/py4j/java_gateway.py", line 1228, in send_command
    raise Py4JNetworkError(
py4j.protocol.Py4JNetworkError: Error while receiving
ERROR:root:Exception while sending command.
Traceback (most recent call last):
  File "/usr/local/lib/python3.8/dist-packages/py4j/java_gateway.py", line 1224, in send_command
    raise Py4JNetworkError("Answer from Java side is empty")
py4j.protocol.Py4JNetworkError: Answer from Java side is empty

During handling of the above exception, another exception occurred:

Traceback (most recent call last):
  File "/usr/local/lib/python3.8/dist-packages/py4j/java_gateway.py", line 1038, in send_command
    response = connection.send_command(command)
  File "/usr/local/lib/python3.8/dist-packages/py4j/java_gateway.py", line 1228, in send_command
    raise Py4JNetworkError(
py4j.protocol.Py4JNetworkError: Error while receiving
ERROR:root:Exception while sending command.
Traceback (most recent call last):
  File "/usr/local/lib/python3.8/dist-packages/py4j/java_gateway.py", line 1224, in send_command
    raise Py4JNetworkError("Answer from Java side is empty")
py4j.protocol.Py4JNetworkError: Answer from Java side is empty

During handling of the above exception, another exception occurred:

Traceback (most recent call last):
  File "/usr/local/lib/python3.8/dist-packages/py4j/java_gateway.py", line 1038, in send_command
    response = connection.send_command(command)
  File "/usr/local/lib/python3.8/dist-packages/py4j/java_gateway.py", line 1228, in send_command
    raise Py4JNetworkError(
py4j.protocol.Py4JNetworkError: Error while receiving
ERROR:root:Exception while sending command.
Traceback (most recent call last):
  File "/usr/local/lib/python3.8/dist-packages/py4j/java_gateway.py", line 1224, in send_command
    raise Py4JNetworkError("Answer from Java side is empty")
py4j.protocol.Py4JNetworkError: Answer from Java side is empty

During handling of the above exception, another exception occurred:

Traceback (most recent call last):
  File "/usr/local/lib/python3.8/dist-packages/py4j/java_gateway.py", line 1038, in send_command
    response = connection.send_command(command)
  File "/usr/local/lib/python3.8/dist-packages/py4j/java_gateway.py", line 1228, in send_command
    raise Py4JNetworkError(
py4j.protocol.Py4JNetworkError: Error while receiving
ERROR:root:Exception while sending command.
Traceback (most recent call last):
  File "/usr/local/lib/python3.8/dist-packages/py4j/java_gateway.py", line 1224, in send_command
    raise Py4JNetworkError("Answer from Java side is empty")
py4j.protocol.Py4JNetworkError: Answer from Java side is empty

During handling of the above exception, another exception occurred:

Traceback (most recent call last):
  File "/usr/local/lib/python3.8/dist-packages/py4j/java_gateway.py", line 1038, in send_command
    response = connection.send_command(command)
  File "/usr/local/lib/python3.8/dist-packages/py4j/java_gateway.py", line 1228, in send_command
    raise Py4JNetworkError(
py4j.protocol.Py4JNetworkError: Error while receiving
ERROR:root:Exception while sending command.
Traceback (most recent call last):
  File "/usr/local/lib/python3.8/dist-packages/py4j/java_gateway.py", line 1224, in send_command
    raise Py4JNetworkError("Answer from Java side is empty")
py4j.protocol.Py4JNetworkError: Answer from Java side is empty

During handling of the above exception, another exception occurred:

Traceback (most recent call last):
  File "/usr/local/lib/python3.8/dist-packages/py4j/java_gateway.py", line 1038, in send_command
    response = connection.send_command(command)
  File "/usr/local/lib/python3.8/dist-packages/py4j/java_gateway.py", line 1228, in send_command
    raise Py4JNetworkError(
py4j.protocol.Py4JNetworkError: Error while receiving
ERROR:root:Exception while sending command.
Traceback (most recent call last):
  File "/usr/local/lib/python3.8/dist-packages/py4j/java_gateway.py", line 1224, in send_command
    raise Py4JNetworkError("Answer from Java side is empty")
py4j.protocol.Py4JNetworkError: Answer from Java side is empty

During handling of the above exception, another exception occurred:

Traceback (most recent call last):
  File "/usr/local/lib/python3.8/dist-packages/py4j/java_gateway.py", line 1038, in send_command
    response = connection.send_command(command)
  File "/usr/local/lib/python3.8/dist-packages/py4j/java_gateway.py", line 1228, in send_command
    raise Py4JNetworkError(
py4j.protocol.Py4JNetworkError: Error while receiving
ERROR:root:Exception while sending command.
Traceback (most recent call last):
  File "/usr/local/lib/python3.8/dist-packages/py4j/java_gateway.py", line 1224, in send_command
    raise Py4JNetworkError("Answer from Java side is empty")
py4j.protocol.Py4JNetworkError: Answer from Java side is empty

During handling of the above exception, another exception occurred:

Traceback (most recent call last):
  File "/usr/local/lib/python3.8/dist-packages/py4j/java_gateway.py", line 1038, in send_command
    response = connection.send_command(command)
  File "/usr/local/lib/python3.8/dist-packages/py4j/java_gateway.py", line 1228, in send_command
    raise Py4JNetworkError(
py4j.protocol.Py4JNetworkError: Error while receiving
ERROR:root:Exception while sending command.
Traceback (most recent call last):
  File "/usr/local/lib/python3.8/dist-packages/py4j/java_gateway.py", line 1224, in send_command
    raise Py4JNetworkError("Answer from Java side is empty")
py4j.protocol.Py4JNetworkError: Answer from Java side is empty

During handling of the above exception, another exception occurred:

Traceback (most recent call last):
  File "/usr/local/lib/python3.8/dist-packages/py4j/java_gateway.py", line 1038, in send_command
    response = connection.send_command(command)
  File "/usr/local/lib/python3.8/dist-packages/py4j/java_gateway.py", line 1228, in send_command
    raise Py4JNetworkError(
py4j.protocol.Py4JNetworkError: Error while receiving
ERROR:py4j.java_gateway:There was an exception while executing the Python Proxy on the Python Side.
Traceback (most recent call last):
  File "/usr/local/lib/python3.8/dist-packages/py4j/java_gateway.py", line 2463, in _call_proxy
    return_value = getattr(self.pool[obj_id], method)(*params)
  File "/app/myenv/gym_ai.py", line 111, in processing
    request = self.pipe.recv()
  File "/usr/lib/python3.8/multiprocessing/connection.py", line 250, in recv
    buf = self._recv_bytes()
  File "/usr/lib/python3.8/multiprocessing/connection.py", line 414, in _recv_bytes
    buf = self._recv(4)
  File "/usr/lib/python3.8/multiprocessing/connection.py", line 383, in _recv
    raise EOFError
EOFError
ERROR:root:Exception while sending command.
Traceback (most recent call last):
  File "/usr/local/lib/python3.8/dist-packages/py4j/java_gateway.py", line 1224, in send_command
    raise Py4JNetworkError("Answer from Java side is empty")
py4j.protocol.Py4JNetworkError: Answer from Java side is empty

During handling of the above exception, another exception occurred:

Traceback (most recent call last):
  File "/usr/local/lib/python3.8/dist-packages/py4j/java_gateway.py", line 1038, in send_command
    response = connection.send_command(command)
  File "/usr/local/lib/python3.8/dist-packages/py4j/java_gateway.py", line 1228, in send_command
    raise Py4JNetworkError(
py4j.protocol.Py4JNetworkError: Error while receiving
ERROR:root:Exception while sending command.
Traceback (most recent call last):
  File "/usr/local/lib/python3.8/dist-packages/py4j/java_gateway.py", line 1224, in send_command
    raise Py4JNetworkError("Answer from Java side is empty")
py4j.protocol.Py4JNetworkError: Answer from Java side is empty

During handling of the above exception, another exception occurred:

Traceback (most recent call last):
  File "/usr/local/lib/python3.8/dist-packages/py4j/java_gateway.py", line 1038, in send_command
    response = connection.send_command(command)
  File "/usr/local/lib/python3.8/dist-packages/py4j/java_gateway.py", line 1228, in send_command
    raise Py4JNetworkError(
py4j.protocol.Py4JNetworkError: Error while receiving
ERROR:root:Exception while sending command.
Traceback (most recent call last):
  File "/usr/local/lib/python3.8/dist-packages/py4j/java_gateway.py", line 1224, in send_command
    raise Py4JNetworkError("Answer from Java side is empty")
py4j.protocol.Py4JNetworkError: Answer from Java side is empty

During handling of the above exception, another exception occurred:

Traceback (most recent call last):
  File "/usr/local/lib/python3.8/dist-packages/py4j/java_gateway.py", line 1038, in send_command
    response = connection.send_command(command)
  File "/usr/local/lib/python3.8/dist-packages/py4j/java_gateway.py", line 1228, in send_command
    raise Py4JNetworkError(
py4j.protocol.Py4JNetworkError: Error while receiving
ERROR:root:Exception while sending command.
Traceback (most recent call last):
  File "/usr/local/lib/python3.8/dist-packages/py4j/java_gateway.py", line 1224, in send_command
    raise Py4JNetworkError("Answer from Java side is empty")
py4j.protocol.Py4JNetworkError: Answer from Java side is empty

During handling of the above exception, another exception occurred:

Traceback (most recent call last):
  File "/usr/local/lib/python3.8/dist-packages/py4j/java_gateway.py", line 1038, in send_command
    response = connection.send_command(command)
  File "/usr/local/lib/python3.8/dist-packages/py4j/java_gateway.py", line 1228, in send_command
    raise Py4JNetworkError(
py4j.protocol.Py4JNetworkError: Error while receiving
ERROR:root:Exception while sending command.
Traceback (most recent call last):
  File "/usr/local/lib/python3.8/dist-packages/py4j/java_gateway.py", line 1224, in send_command
    raise Py4JNetworkError("Answer from Java side is empty")
py4j.protocol.Py4JNetworkError: Answer from Java side is empty

During handling of the above exception, another exception occurred:

Traceback (most recent call last):
  File "/usr/local/lib/python3.8/dist-packages/py4j/java_gateway.py", line 1038, in send_command
    response = connection.send_command(command)
  File "/usr/local/lib/python3.8/dist-packages/py4j/java_gateway.py", line 1228, in send_command
    raise Py4JNetworkError(
py4j.protocol.Py4JNetworkError: Error while receiving
ERROR:root:Exception while sending command.
Traceback (most recent call last):
  File "/usr/local/lib/python3.8/dist-packages/py4j/java_gateway.py", line 1224, in send_command
    raise Py4JNetworkError("Answer from Java side is empty")
py4j.protocol.Py4JNetworkError: Answer from Java side is empty

During handling of the above exception, another exception occurred:

Traceback (most recent call last):
  File "/usr/local/lib/python3.8/dist-packages/py4j/java_gateway.py", line 1038, in send_command
    response = connection.send_command(command)
  File "/usr/local/lib/python3.8/dist-packages/py4j/java_gateway.py", line 1228, in send_command
    raise Py4JNetworkError(
py4j.protocol.Py4JNetworkError: Error while receiving
ERROR:root:Exception while sending command.
Traceback (most recent call last):
  File "/usr/local/lib/python3.8/dist-packages/py4j/java_gateway.py", line 1224, in send_command
    raise Py4JNetworkError("Answer from Java side is empty")
py4j.protocol.Py4JNetworkError: Answer from Java side is empty

During handling of the above exception, another exception occurred:

Traceback (most recent call last):
  File "/usr/local/lib/python3.8/dist-packages/py4j/java_gateway.py", line 1038, in send_command
    response = connection.send_command(command)
  File "/usr/local/lib/python3.8/dist-packages/py4j/java_gateway.py", line 1228, in send_command
    raise Py4JNetworkError(
py4j.protocol.Py4JNetworkError: Error while receiving
ERROR:root:Exception while sending command.
Traceback (most recent call last):
  File "/usr/local/lib/python3.8/dist-packages/py4j/java_gateway.py", line 1224, in send_command
    raise Py4JNetworkError("Answer from Java side is empty")
py4j.protocol.Py4JNetworkError: Answer from Java side is empty

During handling of the above exception, another exception occurred:

Traceback (most recent call last):
  File "/usr/local/lib/python3.8/dist-packages/py4j/java_gateway.py", line 1038, in send_command
    response = connection.send_command(command)
  File "/usr/local/lib/python3.8/dist-packages/py4j/java_gateway.py", line 1228, in send_command
    raise Py4JNetworkError(
py4j.protocol.Py4JNetworkError: Error while receiving
ERROR:root:Exception while sending command.
Traceback (most recent call last):
  File "/usr/local/lib/python3.8/dist-packages/py4j/java_gateway.py", line 1224, in send_command
    raise Py4JNetworkError("Answer from Java side is empty")
py4j.protocol.Py4JNetworkError: Answer from Java side is empty

During handling of the above exception, another exception occurred:

Traceback (most recent call last):
  File "/usr/local/lib/python3.8/dist-packages/py4j/java_gateway.py", line 1038, in send_command
    response = connection.send_command(command)
  File "/usr/local/lib/python3.8/dist-packages/py4j/java_gateway.py", line 1228, in send_command
    raise Py4JNetworkError(
py4j.protocol.Py4JNetworkError: Error while receiving
ERROR:root:Exception while sending command.
Traceback (most recent call last):
  File "/usr/local/lib/python3.8/dist-packages/py4j/java_gateway.py", line 1224, in send_command
    raise Py4JNetworkError("Answer from Java side is empty")
py4j.protocol.Py4JNetworkError: Answer from Java side is empty

During handling of the above exception, another exception occurred:

Traceback (most recent call last):
  File "/usr/local/lib/python3.8/dist-packages/py4j/java_gateway.py", line 1038, in send_command
    response = connection.send_command(command)
  File "/usr/local/lib/python3.8/dist-packages/py4j/java_gateway.py", line 1228, in send_command
    raise Py4JNetworkError(
py4j.protocol.Py4JNetworkError: Error while receiving
ERROR:root:Exception while sending command.
Traceback (most recent call last):
  File "/usr/local/lib/python3.8/dist-packages/py4j/java_gateway.py", line 1224, in send_command
    raise Py4JNetworkError("Answer from Java side is empty")
py4j.protocol.Py4JNetworkError: Answer from Java side is empty

During handling of the above exception, another exception occurred:

Traceback (most recent call last):
  File "/usr/local/lib/python3.8/dist-packages/py4j/java_gateway.py", line 1038, in send_command
    response = connection.send_command(command)
  File "/usr/local/lib/python3.8/dist-packages/py4j/java_gateway.py", line 1228, in send_command
    raise Py4JNetworkError(
py4j.protocol.Py4JNetworkError: Error while receiving
ERROR:root:Exception while sending command.
Traceback (most recent call last):
  File "/usr/local/lib/python3.8/dist-packages/py4j/java_gateway.py", line 1224, in send_command
    raise Py4JNetworkError("Answer from Java side is empty")
py4j.protocol.Py4JNetworkError: Answer from Java side is empty

During handling of the above exception, another exception occurred:

Traceback (most recent call last):
  File "/usr/local/lib/python3.8/dist-packages/py4j/java_gateway.py", line 1038, in send_command
    response = connection.send_command(command)
  File "/usr/local/lib/python3.8/dist-packages/py4j/java_gateway.py", line 1228, in send_command
    raise Py4JNetworkError(
py4j.protocol.Py4JNetworkError: Error while receiving
ERROR:root:Exception while sending command.
Traceback (most recent call last):
  File "/usr/local/lib/python3.8/dist-packages/py4j/java_gateway.py", line 1224, in send_command
    raise Py4JNetworkError("Answer from Java side is empty")
py4j.protocol.Py4JNetworkError: Answer from Java side is empty

During handling of the above exception, another exception occurred:

Traceback (most recent call last):
  File "/usr/local/lib/python3.8/dist-packages/py4j/java_gateway.py", line 1038, in send_command
    response = connection.send_command(command)
  File "/usr/local/lib/python3.8/dist-packages/py4j/java_gateway.py", line 1228, in send_command
    raise Py4JNetworkError(
py4j.protocol.Py4JNetworkError: Error while receiving
ERROR:py4j.java_gateway:There was an exception while executing the Python Proxy on the Python Side.
Traceback (most recent call last):
  File "/usr/local/lib/python3.8/dist-packages/py4j/java_gateway.py", line 2463, in _call_proxy
    return_value = getattr(self.pool[obj_id], method)(*params)
  File "/app/myenv/gym_ai.py", line 111, in processing
    request = self.pipe.recv()
  File "/usr/lib/python3.8/multiprocessing/connection.py", line 250, in recv
    buf = self._recv_bytes()
  File "/usr/lib/python3.8/multiprocessing/connection.py", line 414, in _recv_bytes
    buf = self._recv(4)
  File "/usr/lib/python3.8/multiprocessing/connection.py", line 383, in _recv
    raise EOFError
EOFError
ERROR:root:Exception while sending command.
Traceback (most recent call last):
  File "/usr/local/lib/python3.8/dist-packages/py4j/java_gateway.py", line 1224, in send_command
    raise Py4JNetworkError("Answer from Java side is empty")
py4j.protocol.Py4JNetworkError: Answer from Java side is empty

During handling of the above exception, another exception occurred:

Traceback (most recent call last):
  File "/usr/local/lib/python3.8/dist-packages/py4j/java_gateway.py", line 1038, in send_command
    response = connection.send_command(command)
  File "/usr/local/lib/python3.8/dist-packages/py4j/java_gateway.py", line 1228, in send_command
    raise Py4JNetworkError(
py4j.protocol.Py4JNetworkError: Error while receiving
ERROR:root:Exception while sending command.
Traceback (most recent call last):
  File "/usr/local/lib/python3.8/dist-packages/py4j/java_gateway.py", line 1224, in send_command
    raise Py4JNetworkError("Answer from Java side is empty")
py4j.protocol.Py4JNetworkError: Answer from Java side is empty

During handling of the above exception, another exception occurred:

Traceback (most recent call last):
  File "/usr/local/lib/python3.8/dist-packages/py4j/java_gateway.py", line 1038, in send_command
    response = connection.send_command(command)
  File "/usr/local/lib/python3.8/dist-packages/py4j/java_gateway.py", line 1228, in send_command
    raise Py4JNetworkError(
py4j.protocol.Py4JNetworkError: Error while receiving
ERROR:root:Exception while sending command.
Traceback (most recent call last):
  File "/usr/local/lib/python3.8/dist-packages/py4j/java_gateway.py", line 1224, in send_command
    raise Py4JNetworkError("Answer from Java side is empty")
py4j.protocol.Py4JNetworkError: Answer from Java side is empty

During handling of the above exception, another exception occurred:

Traceback (most recent call last):
  File "/usr/local/lib/python3.8/dist-packages/py4j/java_gateway.py", line 1038, in send_command
    response = connection.send_command(command)
  File "/usr/local/lib/python3.8/dist-packages/py4j/java_gateway.py", line 1228, in send_command
    raise Py4JNetworkError(
py4j.protocol.Py4JNetworkError: Error while receiving
ERROR:root:Exception while sending command.
Traceback (most recent call last):
  File "/usr/local/lib/python3.8/dist-packages/py4j/java_gateway.py", line 1224, in send_command
    raise Py4JNetworkError("Answer from Java side is empty")
py4j.protocol.Py4JNetworkError: Answer from Java side is empty

During handling of the above exception, another exception occurred:

Traceback (most recent call last):
  File "/usr/local/lib/python3.8/dist-packages/py4j/java_gateway.py", line 1038, in send_command
    response = connection.send_command(command)
  File "/usr/local/lib/python3.8/dist-packages/py4j/java_gateway.py", line 1228, in send_command
    raise Py4JNetworkError(
py4j.protocol.Py4JNetworkError: Error while receiving
ERROR:root:Exception while sending command.
Traceback (most recent call last):
  File "/usr/local/lib/python3.8/dist-packages/py4j/java_gateway.py", line 1224, in send_command
    raise Py4JNetworkError("Answer from Java side is empty")
py4j.protocol.Py4JNetworkError: Answer from Java side is empty

During handling of the above exception, another exception occurred:

Traceback (most recent call last):
  File "/usr/local/lib/python3.8/dist-packages/py4j/java_gateway.py", line 1038, in send_command
    response = connection.send_command(command)
  File "/usr/local/lib/python3.8/dist-packages/py4j/java_gateway.py", line 1228, in send_command
    raise Py4JNetworkError(
py4j.protocol.Py4JNetworkError: Error while receiving
ERROR:root:Exception while sending command.
Traceback (most recent call last):
  File "/usr/local/lib/python3.8/dist-packages/py4j/java_gateway.py", line 1224, in send_command
    raise Py4JNetworkError("Answer from Java side is empty")
py4j.protocol.Py4JNetworkError: Answer from Java side is empty

During handling of the above exception, another exception occurred:

Traceback (most recent call last):
  File "/usr/local/lib/python3.8/dist-packages/py4j/java_gateway.py", line 1038, in send_command
    response = connection.send_command(command)
  File "/usr/local/lib/python3.8/dist-packages/py4j/java_gateway.py", line 1228, in send_command
    raise Py4JNetworkError(
py4j.protocol.Py4JNetworkError: Error while receiving
ERROR:root:Exception while sending command.
Traceback (most recent call last):
  File "/usr/local/lib/python3.8/dist-packages/py4j/java_gateway.py", line 1224, in send_command
    raise Py4JNetworkError("Answer from Java side is empty")
py4j.protocol.Py4JNetworkError: Answer from Java side is empty

During handling of the above exception, another exception occurred:

Traceback (most recent call last):
  File "/usr/local/lib/python3.8/dist-packages/py4j/java_gateway.py", line 1038, in send_command
    response = connection.send_command(command)
  File "/usr/local/lib/python3.8/dist-packages/py4j/java_gateway.py", line 1228, in send_command
    raise Py4JNetworkError(
py4j.protocol.Py4JNetworkError: Error while receiving
ERROR:root:Exception while sending command.
Traceback (most recent call last):
  File "/usr/local/lib/python3.8/dist-packages/py4j/java_gateway.py", line 1224, in send_command
    raise Py4JNetworkError("Answer from Java side is empty")
py4j.protocol.Py4JNetworkError: Answer from Java side is empty

During handling of the above exception, another exception occurred:

Traceback (most recent call last):
  File "/usr/local/lib/python3.8/dist-packages/py4j/java_gateway.py", line 1038, in send_command
    response = connection.send_command(command)
  File "/usr/local/lib/python3.8/dist-packages/py4j/java_gateway.py", line 1228, in send_command
    raise Py4JNetworkError(
py4j.protocol.Py4JNetworkError: Error while receiving
ERROR:root:Exception while sending command.
Traceback (most recent call last):
  File "/usr/local/lib/python3.8/dist-packages/py4j/java_gateway.py", line 1224, in send_command
    raise Py4JNetworkError("Answer from Java side is empty")
py4j.protocol.Py4JNetworkError: Answer from Java side is empty

During handling of the above exception, another exception occurred:

Traceback (most recent call last):
  File "/usr/local/lib/python3.8/dist-packages/py4j/java_gateway.py", line 1038, in send_command
    response = connection.send_command(command)
  File "/usr/local/lib/python3.8/dist-packages/py4j/java_gateway.py", line 1228, in send_command
    raise Py4JNetworkError(
py4j.protocol.Py4JNetworkError: Error while receiving
ERROR:root:Exception while sending command.
Traceback (most recent call last):
  File "/usr/local/lib/python3.8/dist-packages/py4j/java_gateway.py", line 1224, in send_command
    raise Py4JNetworkError("Answer from Java side is empty")
py4j.protocol.Py4JNetworkError: Answer from Java side is empty

During handling of the above exception, another exception occurred:

Traceback (most recent call last):
  File "/usr/local/lib/python3.8/dist-packages/py4j/java_gateway.py", line 1038, in send_command
    response = connection.send_command(command)
  File "/usr/local/lib/python3.8/dist-packages/py4j/java_gateway.py", line 1228, in send_command
    raise Py4JNetworkError(
py4j.protocol.Py4JNetworkError: Error while receiving
ERROR:root:Exception while sending command.
Traceback (most recent call last):
  File "/usr/local/lib/python3.8/dist-packages/py4j/java_gateway.py", line 1224, in send_command
    raise Py4JNetworkError("Answer from Java side is empty")
py4j.protocol.Py4JNetworkError: Answer from Java side is empty

During handling of the above exception, another exception occurred:

Traceback (most recent call last):
  File "/usr/local/lib/python3.8/dist-packages/py4j/java_gateway.py", line 1038, in send_command
    response = connection.send_command(command)
  File "/usr/local/lib/python3.8/dist-packages/py4j/java_gateway.py", line 1228, in send_command
    raise Py4JNetworkError(
py4j.protocol.Py4JNetworkError: Error while receiving
ERROR:root:Exception while sending command.
Traceback (most recent call last):
  File "/usr/local/lib/python3.8/dist-packages/py4j/java_gateway.py", line 1224, in send_command
    raise Py4JNetworkError("Answer from Java side is empty")
py4j.protocol.Py4JNetworkError: Answer from Java side is empty

During handling of the above exception, another exception occurred:

Traceback (most recent call last):
  File "/usr/local/lib/python3.8/dist-packages/py4j/java_gateway.py", line 1038, in send_command
    response = connection.send_command(command)
  File "/usr/local/lib/python3.8/dist-packages/py4j/java_gateway.py", line 1228, in send_command
    raise Py4JNetworkError(
py4j.protocol.Py4JNetworkError: Error while receiving
ERROR:root:Exception while sending command.
Traceback (most recent call last):
  File "/usr/local/lib/python3.8/dist-packages/py4j/java_gateway.py", line 1224, in send_command
    raise Py4JNetworkError("Answer from Java side is empty")
py4j.protocol.Py4JNetworkError: Answer from Java side is empty

During handling of the above exception, another exception occurred:

Traceback (most recent call last):
  File "/usr/local/lib/python3.8/dist-packages/py4j/java_gateway.py", line 1038, in send_command
    response = connection.send_command(command)
  File "/usr/local/lib/python3.8/dist-packages/py4j/java_gateway.py", line 1228, in send_command
    raise Py4JNetworkError(
py4j.protocol.Py4JNetworkError: Error while receiving
ERROR:root:Exception while sending command.
Traceback (most recent call last):
  File "/usr/local/lib/python3.8/dist-packages/py4j/java_gateway.py", line 1224, in send_command
    raise Py4JNetworkError("Answer from Java side is empty")
py4j.protocol.Py4JNetworkError: Answer from Java side is empty

During handling of the above exception, another exception occurred:

Traceback (most recent call last):
  File "/usr/local/lib/python3.8/dist-packages/py4j/java_gateway.py", line 1038, in send_command
    response = connection.send_command(command)
  File "/usr/local/lib/python3.8/dist-packages/py4j/java_gateway.py", line 1228, in send_command
    raise Py4JNetworkError(
py4j.protocol.Py4JNetworkError: Error while receiving
ERROR:py4j.java_gateway:There was an exception while executing the Python Proxy on the Python Side.
Traceback (most recent call last):
  File "/usr/local/lib/python3.8/dist-packages/py4j/java_gateway.py", line 2463, in _call_proxy
    return_value = getattr(self.pool[obj_id], method)(*params)
  File "/app/myenv/gym_ai.py", line 111, in processing
    request = self.pipe.recv()
  File "/usr/lib/python3.8/multiprocessing/connection.py", line 250, in recv
    buf = self._recv_bytes()
  File "/usr/lib/python3.8/multiprocessing/connection.py", line 414, in _recv_bytes
    buf = self._recv(4)
  File "/usr/lib/python3.8/multiprocessing/connection.py", line 383, in _recv
    raise EOFError
EOFError
ERROR:root:Exception while sending command.
Traceback (most recent call last):
  File "/usr/local/lib/python3.8/dist-packages/py4j/java_gateway.py", line 1224, in send_command
    raise Py4JNetworkError("Answer from Java side is empty")
py4j.protocol.Py4JNetworkError: Answer from Java side is empty

During handling of the above exception, another exception occurred:

Traceback (most recent call last):
  File "/usr/local/lib/python3.8/dist-packages/py4j/java_gateway.py", line 1038, in send_command
    response = connection.send_command(command)
  File "/usr/local/lib/python3.8/dist-packages/py4j/java_gateway.py", line 1228, in send_command
    raise Py4JNetworkError(
py4j.protocol.Py4JNetworkError: Error while receiving
ERROR:root:Exception while sending command.
Traceback (most recent call last):
  File "/usr/local/lib/python3.8/dist-packages/py4j/java_gateway.py", line 1224, in send_command
    raise Py4JNetworkError("Answer from Java side is empty")
py4j.protocol.Py4JNetworkError: Answer from Java side is empty

During handling of the above exception, another exception occurred:

Traceback (most recent call last):
  File "/usr/local/lib/python3.8/dist-packages/py4j/java_gateway.py", line 1038, in send_command
    response = connection.send_command(command)
  File "/usr/local/lib/python3.8/dist-packages/py4j/java_gateway.py", line 1228, in send_command
    raise Py4JNetworkError(
py4j.protocol.Py4JNetworkError: Error while receiving
ERROR:root:Exception while sending command.
Traceback (most recent call last):
  File "/usr/local/lib/python3.8/dist-packages/py4j/java_gateway.py", line 1224, in send_command
    raise Py4JNetworkError("Answer from Java side is empty")
py4j.protocol.Py4JNetworkError: Answer from Java side is empty

During handling of the above exception, another exception occurred:

Traceback (most recent call last):
  File "/usr/local/lib/python3.8/dist-packages/py4j/java_gateway.py", line 1038, in send_command
    response = connection.send_command(command)
  File "/usr/local/lib/python3.8/dist-packages/py4j/java_gateway.py", line 1228, in send_command
    raise Py4JNetworkError(
py4j.protocol.Py4JNetworkError: Error while receiving
ERROR:root:Exception while sending command.
Traceback (most recent call last):
  File "/usr/local/lib/python3.8/dist-packages/py4j/java_gateway.py", line 1224, in send_command
    raise Py4JNetworkError("Answer from Java side is empty")
py4j.protocol.Py4JNetworkError: Answer from Java side is empty

During handling of the above exception, another exception occurred:

Traceback (most recent call last):
  File "/usr/local/lib/python3.8/dist-packages/py4j/java_gateway.py", line 1038, in send_command
    response = connection.send_command(command)
  File "/usr/local/lib/python3.8/dist-packages/py4j/java_gateway.py", line 1228, in send_command
    raise Py4JNetworkError(
py4j.protocol.Py4JNetworkError: Error while receiving
ERROR:root:Exception while sending command.
Traceback (most recent call last):
  File "/usr/local/lib/python3.8/dist-packages/py4j/java_gateway.py", line 1224, in send_command
    raise Py4JNetworkError("Answer from Java side is empty")
py4j.protocol.Py4JNetworkError: Answer from Java side is empty

During handling of the above exception, another exception occurred:

Traceback (most recent call last):
  File "/usr/local/lib/python3.8/dist-packages/py4j/java_gateway.py", line 1038, in send_command
    response = connection.send_command(command)
  File "/usr/local/lib/python3.8/dist-packages/py4j/java_gateway.py", line 1228, in send_command
    raise Py4JNetworkError(
py4j.protocol.Py4JNetworkError: Error while receiving
ERROR:root:Exception while sending command.
Traceback (most recent call last):
  File "/usr/local/lib/python3.8/dist-packages/py4j/java_gateway.py", line 1224, in send_command
    raise Py4JNetworkError("Answer from Java side is empty")
py4j.protocol.Py4JNetworkError: Answer from Java side is empty

During handling of the above exception, another exception occurred:

Traceback (most recent call last):
  File "/usr/local/lib/python3.8/dist-packages/py4j/java_gateway.py", line 1038, in send_command
    response = connection.send_command(command)
  File "/usr/local/lib/python3.8/dist-packages/py4j/java_gateway.py", line 1228, in send_command
    raise Py4JNetworkError(
py4j.protocol.Py4JNetworkError: Error while receiving
ERROR:root:Exception while sending command.
Traceback (most recent call last):
  File "/usr/local/lib/python3.8/dist-packages/py4j/java_gateway.py", line 1224, in send_command
    raise Py4JNetworkError("Answer from Java side is empty")
py4j.protocol.Py4JNetworkError: Answer from Java side is empty

During handling of the above exception, another exception occurred:

Traceback (most recent call last):
  File "/usr/local/lib/python3.8/dist-packages/py4j/java_gateway.py", line 1038, in send_command
    response = connection.send_command(command)
  File "/usr/local/lib/python3.8/dist-packages/py4j/java_gateway.py", line 1228, in send_command
    raise Py4JNetworkError(
py4j.protocol.Py4JNetworkError: Error while receiving
ERROR:root:Exception while sending command.
Traceback (most recent call last):
  File "/usr/local/lib/python3.8/dist-packages/py4j/java_gateway.py", line 1224, in send_command
    raise Py4JNetworkError("Answer from Java side is empty")
py4j.protocol.Py4JNetworkError: Answer from Java side is empty

During handling of the above exception, another exception occurred:

Traceback (most recent call last):
  File "/usr/local/lib/python3.8/dist-packages/py4j/java_gateway.py", line 1038, in send_command
    response = connection.send_command(command)
  File "/usr/local/lib/python3.8/dist-packages/py4j/java_gateway.py", line 1228, in send_command
    raise Py4JNetworkError(
py4j.protocol.Py4JNetworkError: Error while receiving
ERROR:root:Exception while sending command.
Traceback (most recent call last):
  File "/usr/local/lib/python3.8/dist-packages/py4j/java_gateway.py", line 1224, in send_command
    raise Py4JNetworkError("Answer from Java side is empty")
py4j.protocol.Py4JNetworkError: Answer from Java side is empty

During handling of the above exception, another exception occurred:

Traceback (most recent call last):
  File "/usr/local/lib/python3.8/dist-packages/py4j/java_gateway.py", line 1038, in send_command
    response = connection.send_command(command)
  File "/usr/local/lib/python3.8/dist-packages/py4j/java_gateway.py", line 1228, in send_command
    raise Py4JNetworkError(
py4j.protocol.Py4JNetworkError: Error while receiving
ERROR:root:Exception while sending command.
Traceback (most recent call last):
  File "/usr/local/lib/python3.8/dist-packages/py4j/java_gateway.py", line 1224, in send_command
    raise Py4JNetworkError("Answer from Java side is empty")
py4j.protocol.Py4JNetworkError: Answer from Java side is empty

During handling of the above exception, another exception occurred:

Traceback (most recent call last):
  File "/usr/local/lib/python3.8/dist-packages/py4j/java_gateway.py", line 1038, in send_command
    response = connection.send_command(command)
  File "/usr/local/lib/python3.8/dist-packages/py4j/java_gateway.py", line 1228, in send_command
    raise Py4JNetworkError(
py4j.protocol.Py4JNetworkError: Error while receiving
ERROR:root:Exception while sending command.
Traceback (most recent call last):
  File "/usr/local/lib/python3.8/dist-packages/py4j/java_gateway.py", line 1224, in send_command
    raise Py4JNetworkError("Answer from Java side is empty")
py4j.protocol.Py4JNetworkError: Answer from Java side is empty

During handling of the above exception, another exception occurred:

Traceback (most recent call last):
  File "/usr/local/lib/python3.8/dist-packages/py4j/java_gateway.py", line 1038, in send_command
    response = connection.send_command(command)
  File "/usr/local/lib/python3.8/dist-packages/py4j/java_gateway.py", line 1228, in send_command
    raise Py4JNetworkError(
py4j.protocol.Py4JNetworkError: Error while receiving
ERROR:root:Exception while sending command.
Traceback (most recent call last):
  File "/usr/local/lib/python3.8/dist-packages/py4j/java_gateway.py", line 1224, in send_command
    raise Py4JNetworkError("Answer from Java side is empty")
py4j.protocol.Py4JNetworkError: Answer from Java side is empty

During handling of the above exception, another exception occurred:

Traceback (most recent call last):
  File "/usr/local/lib/python3.8/dist-packages/py4j/java_gateway.py", line 1038, in send_command
    response = connection.send_command(command)
  File "/usr/local/lib/python3.8/dist-packages/py4j/java_gateway.py", line 1228, in send_command
    raise Py4JNetworkError(
py4j.protocol.Py4JNetworkError: Error while receiving
ERROR:root:Exception while sending command.
Traceback (most recent call last):
  File "/usr/local/lib/python3.8/dist-packages/py4j/java_gateway.py", line 1224, in send_command
    raise Py4JNetworkError("Answer from Java side is empty")
py4j.protocol.Py4JNetworkError: Answer from Java side is empty

During handling of the above exception, another exception occurred:

Traceback (most recent call last):
  File "/usr/local/lib/python3.8/dist-packages/py4j/java_gateway.py", line 1038, in send_command
    response = connection.send_command(command)
  File "/usr/local/lib/python3.8/dist-packages/py4j/java_gateway.py", line 1228, in send_command
    raise Py4JNetworkError(
py4j.protocol.Py4JNetworkError: Error while receiving
ERROR:root:Exception while sending command.
Traceback (most recent call last):
  File "/usr/local/lib/python3.8/dist-packages/py4j/java_gateway.py", line 1224, in send_command
    raise Py4JNetworkError("Answer from Java side is empty")
py4j.protocol.Py4JNetworkError: Answer from Java side is empty

During handling of the above exception, another exception occurred:

Traceback (most recent call last):
  File "/usr/local/lib/python3.8/dist-packages/py4j/java_gateway.py", line 1038, in send_command
    response = connection.send_command(command)
  File "/usr/local/lib/python3.8/dist-packages/py4j/java_gateway.py", line 1228, in send_command
    raise Py4JNetworkError(
py4j.protocol.Py4JNetworkError: Error while receiving
ERROR:root:Exception while sending command.
Traceback (most recent call last):
  File "/usr/local/lib/python3.8/dist-packages/py4j/java_gateway.py", line 1224, in send_command
    raise Py4JNetworkError("Answer from Java side is empty")
py4j.protocol.Py4JNetworkError: Answer from Java side is empty

During handling of the above exception, another exception occurred:

Traceback (most recent call last):
  File "/usr/local/lib/python3.8/dist-packages/py4j/java_gateway.py", line 1038, in send_command
    response = connection.send_command(command)
  File "/usr/local/lib/python3.8/dist-packages/py4j/java_gateway.py", line 1228, in send_command
    raise Py4JNetworkError(
py4j.protocol.Py4JNetworkError: Error while receiving
ERROR:root:Exception while sending command.
Traceback (most recent call last):
  File "/usr/local/lib/python3.8/dist-packages/py4j/java_gateway.py", line 1224, in send_command
    raise Py4JNetworkError("Answer from Java side is empty")
py4j.protocol.Py4JNetworkError: Answer from Java side is empty

During handling of the above exception, another exception occurred:

Traceback (most recent call last):
  File "/usr/local/lib/python3.8/dist-packages/py4j/java_gateway.py", line 1038, in send_command
    response = connection.send_command(command)
  File "/usr/local/lib/python3.8/dist-packages/py4j/java_gateway.py", line 1228, in send_command
    raise Py4JNetworkError(
py4j.protocol.Py4JNetworkError: Error while receiving
ERROR:py4j.java_gateway:There was an exception while executing the Python Proxy on the Python Side.
Traceback (most recent call last):
  File "/usr/local/lib/python3.8/dist-packages/py4j/java_gateway.py", line 2463, in _call_proxy
    return_value = getattr(self.pool[obj_id], method)(*params)
  File "/app/myenv/gym_ai.py", line 111, in processing
    request = self.pipe.recv()
  File "/usr/lib/python3.8/multiprocessing/connection.py", line 250, in recv
    buf = self._recv_bytes()
  File "/usr/lib/python3.8/multiprocessing/connection.py", line 414, in _recv_bytes
    buf = self._recv(4)
  File "/usr/lib/python3.8/multiprocessing/connection.py", line 383, in _recv
    raise EOFError
EOFError
ERROR:root:Exception while sending command.
Traceback (most recent call last):
  File "/usr/local/lib/python3.8/dist-packages/py4j/java_gateway.py", line 1224, in send_command
    raise Py4JNetworkError("Answer from Java side is empty")
py4j.protocol.Py4JNetworkError: Answer from Java side is empty

During handling of the above exception, another exception occurred:

Traceback (most recent call last):
  File "/usr/local/lib/python3.8/dist-packages/py4j/java_gateway.py", line 1038, in send_command
    response = connection.send_command(command)
  File "/usr/local/lib/python3.8/dist-packages/py4j/java_gateway.py", line 1228, in send_command
    raise Py4JNetworkError(
py4j.protocol.Py4JNetworkError: Error while receiving
ERROR:root:Exception while sending command.
Traceback (most recent call last):
  File "/usr/local/lib/python3.8/dist-packages/py4j/java_gateway.py", line 1224, in send_command
    raise Py4JNetworkError("Answer from Java side is empty")
py4j.protocol.Py4JNetworkError: Answer from Java side is empty

During handling of the above exception, another exception occurred:

Traceback (most recent call last):
  File "/usr/local/lib/python3.8/dist-packages/py4j/java_gateway.py", line 1038, in send_command
    response = connection.send_command(command)
  File "/usr/local/lib/python3.8/dist-packages/py4j/java_gateway.py", line 1228, in send_command
    raise Py4JNetworkError(
py4j.protocol.Py4JNetworkError: Error while receiving
ERROR:root:Exception while sending command.
Traceback (most recent call last):
  File "/usr/local/lib/python3.8/dist-packages/py4j/java_gateway.py", line 1224, in send_command
    raise Py4JNetworkError("Answer from Java side is empty")
py4j.protocol.Py4JNetworkError: Answer from Java side is empty

During handling of the above exception, another exception occurred:

Traceback (most recent call last):
  File "/usr/local/lib/python3.8/dist-packages/py4j/java_gateway.py", line 1038, in send_command
    response = connection.send_command(command)
  File "/usr/local/lib/python3.8/dist-packages/py4j/java_gateway.py", line 1228, in send_command
    raise Py4JNetworkError(
py4j.protocol.Py4JNetworkError: Error while receiving
ERROR:root:Exception while sending command.
Traceback (most recent call last):
  File "/usr/local/lib/python3.8/dist-packages/py4j/java_gateway.py", line 1224, in send_command
    raise Py4JNetworkError("Answer from Java side is empty")
py4j.protocol.Py4JNetworkError: Answer from Java side is empty

During handling of the above exception, another exception occurred:

Traceback (most recent call last):
  File "/usr/local/lib/python3.8/dist-packages/py4j/java_gateway.py", line 1038, in send_command
    response = connection.send_command(command)
  File "/usr/local/lib/python3.8/dist-packages/py4j/java_gateway.py", line 1228, in send_command
    raise Py4JNetworkError(
py4j.protocol.Py4JNetworkError: Error while receiving
ERROR:root:Exception while sending command.
Traceback (most recent call last):
  File "/usr/local/lib/python3.8/dist-packages/py4j/java_gateway.py", line 1224, in send_command
    raise Py4JNetworkError("Answer from Java side is empty")
py4j.protocol.Py4JNetworkError: Answer from Java side is empty

During handling of the above exception, another exception occurred:

Traceback (most recent call last):
  File "/usr/local/lib/python3.8/dist-packages/py4j/java_gateway.py", line 1038, in send_command
    response = connection.send_command(command)
  File "/usr/local/lib/python3.8/dist-packages/py4j/java_gateway.py", line 1228, in send_command
    raise Py4JNetworkError(
py4j.protocol.Py4JNetworkError: Error while receiving
ERROR:root:Exception while sending command.
Traceback (most recent call last):
  File "/usr/local/lib/python3.8/dist-packages/py4j/java_gateway.py", line 1224, in send_command
    raise Py4JNetworkError("Answer from Java side is empty")
py4j.protocol.Py4JNetworkError: Answer from Java side is empty

During handling of the above exception, another exception occurred:

Traceback (most recent call last):
  File "/usr/local/lib/python3.8/dist-packages/py4j/java_gateway.py", line 1038, in send_command
    response = connection.send_command(command)
  File "/usr/local/lib/python3.8/dist-packages/py4j/java_gateway.py", line 1228, in send_command
    raise Py4JNetworkError(
py4j.protocol.Py4JNetworkError: Error while receiving
ERROR:root:Exception while sending command.
Traceback (most recent call last):
  File "/usr/local/lib/python3.8/dist-packages/py4j/java_gateway.py", line 1224, in send_command
    raise Py4JNetworkError("Answer from Java side is empty")
py4j.protocol.Py4JNetworkError: Answer from Java side is empty

During handling of the above exception, another exception occurred:

Traceback (most recent call last):
  File "/usr/local/lib/python3.8/dist-packages/py4j/java_gateway.py", line 1038, in send_command
    response = connection.send_command(command)
  File "/usr/local/lib/python3.8/dist-packages/py4j/java_gateway.py", line 1228, in send_command
    raise Py4JNetworkError(
py4j.protocol.Py4JNetworkError: Error while receiving
ERROR:root:Exception while sending command.
Traceback (most recent call last):
  File "/usr/local/lib/python3.8/dist-packages/py4j/java_gateway.py", line 1224, in send_command
    raise Py4JNetworkError("Answer from Java side is empty")
py4j.protocol.Py4JNetworkError: Answer from Java side is empty

During handling of the above exception, another exception occurred:

Traceback (most recent call last):
  File "/usr/local/lib/python3.8/dist-packages/py4j/java_gateway.py", line 1038, in send_command
    response = connection.send_command(command)
  File "/usr/local/lib/python3.8/dist-packages/py4j/java_gateway.py", line 1228, in send_command
    raise Py4JNetworkError(
py4j.protocol.Py4JNetworkError: Error while receiving
ERROR:root:Exception while sending command.
Traceback (most recent call last):
  File "/usr/local/lib/python3.8/dist-packages/py4j/java_gateway.py", line 1224, in send_command
    raise Py4JNetworkError("Answer from Java side is empty")
py4j.protocol.Py4JNetworkError: Answer from Java side is empty

During handling of the above exception, another exception occurred:

Traceback (most recent call last):
  File "/usr/local/lib/python3.8/dist-packages/py4j/java_gateway.py", line 1038, in send_command
    response = connection.send_command(command)
  File "/usr/local/lib/python3.8/dist-packages/py4j/java_gateway.py", line 1228, in send_command
    raise Py4JNetworkError(
py4j.protocol.Py4JNetworkError: Error while receiving
ERROR:root:Exception while sending command.
Traceback (most recent call last):
  File "/usr/local/lib/python3.8/dist-packages/py4j/java_gateway.py", line 1224, in send_command
    raise Py4JNetworkError("Answer from Java side is empty")
py4j.protocol.Py4JNetworkError: Answer from Java side is empty

During handling of the above exception, another exception occurred:

Traceback (most recent call last):
  File "/usr/local/lib/python3.8/dist-packages/py4j/java_gateway.py", line 1038, in send_command
    response = connection.send_command(command)
  File "/usr/local/lib/python3.8/dist-packages/py4j/java_gateway.py", line 1228, in send_command
    raise Py4JNetworkError(
py4j.protocol.Py4JNetworkError: Error while receiving
ERROR:root:Exception while sending command.
Traceback (most recent call last):
  File "/usr/local/lib/python3.8/dist-packages/py4j/java_gateway.py", line 1224, in send_command
    raise Py4JNetworkError("Answer from Java side is empty")
py4j.protocol.Py4JNetworkError: Answer from Java side is empty

During handling of the above exception, another exception occurred:

Traceback (most recent call last):
  File "/usr/local/lib/python3.8/dist-packages/py4j/java_gateway.py", line 1038, in send_command
    response = connection.send_command(command)
  File "/usr/local/lib/python3.8/dist-packages/py4j/java_gateway.py", line 1228, in send_command
    raise Py4JNetworkError(
py4j.protocol.Py4JNetworkError: Error while receiving
ERROR:root:Exception while sending command.
Traceback (most recent call last):
  File "/usr/local/lib/python3.8/dist-packages/py4j/java_gateway.py", line 1224, in send_command
    raise Py4JNetworkError("Answer from Java side is empty")
py4j.protocol.Py4JNetworkError: Answer from Java side is empty

During handling of the above exception, another exception occurred:

Traceback (most recent call last):
  File "/usr/local/lib/python3.8/dist-packages/py4j/java_gateway.py", line 1038, in send_command
    response = connection.send_command(command)
  File "/usr/local/lib/python3.8/dist-packages/py4j/java_gateway.py", line 1228, in send_command
    raise Py4JNetworkError(
py4j.protocol.Py4JNetworkError: Error while receiving
ERROR:root:Exception while sending command.
Traceback (most recent call last):
  File "/usr/local/lib/python3.8/dist-packages/py4j/java_gateway.py", line 1224, in send_command
    raise Py4JNetworkError("Answer from Java side is empty")
py4j.protocol.Py4JNetworkError: Answer from Java side is empty

During handling of the above exception, another exception occurred:

Traceback (most recent call last):
  File "/usr/local/lib/python3.8/dist-packages/py4j/java_gateway.py", line 1038, in send_command
    response = connection.send_command(command)
  File "/usr/local/lib/python3.8/dist-packages/py4j/java_gateway.py", line 1228, in send_command
    raise Py4JNetworkError(
py4j.protocol.Py4JNetworkError: Error while receiving
ERROR:root:Exception while sending command.
Traceback (most recent call last):
  File "/usr/local/lib/python3.8/dist-packages/py4j/java_gateway.py", line 1224, in send_command
    raise Py4JNetworkError("Answer from Java side is empty")
py4j.protocol.Py4JNetworkError: Answer from Java side is empty

During handling of the above exception, another exception occurred:

Traceback (most recent call last):
  File "/usr/local/lib/python3.8/dist-packages/py4j/java_gateway.py", line 1038, in send_command
    response = connection.send_command(command)
  File "/usr/local/lib/python3.8/dist-packages/py4j/java_gateway.py", line 1228, in send_command
    raise Py4JNetworkError(
py4j.protocol.Py4JNetworkError: Error while receiving
ERROR:py4j.java_gateway:There was an exception while executing the Python Proxy on the Python Side.
Traceback (most recent call last):
  File "/usr/local/lib/python3.8/dist-packages/py4j/java_gateway.py", line 2463, in _call_proxy
    return_value = getattr(self.pool[obj_id], method)(*params)
  File "/app/myenv/gym_ai.py", line 111, in processing
    request = self.pipe.recv()
  File "/usr/lib/python3.8/multiprocessing/connection.py", line 250, in recv
    buf = self._recv_bytes()
  File "/usr/lib/python3.8/multiprocessing/connection.py", line 414, in _recv_bytes
    buf = self._recv(4)
  File "/usr/lib/python3.8/multiprocessing/connection.py", line 383, in _recv
    raise EOFError
EOFError
ERROR:root:Exception while sending command.
Traceback (most recent call last):
  File "/usr/local/lib/python3.8/dist-packages/py4j/java_gateway.py", line 1224, in send_command
    raise Py4JNetworkError("Answer from Java side is empty")
py4j.protocol.Py4JNetworkError: Answer from Java side is empty

During handling of the above exception, another exception occurred:

Traceback (most recent call last):
  File "/usr/local/lib/python3.8/dist-packages/py4j/java_gateway.py", line 1038, in send_command
    response = connection.send_command(command)
  File "/usr/local/lib/python3.8/dist-packages/py4j/java_gateway.py", line 1228, in send_command
    raise Py4JNetworkError(
py4j.protocol.Py4JNetworkError: Error while receiving
ERROR:root:Exception while sending command.
Traceback (most recent call last):
  File "/usr/local/lib/python3.8/dist-packages/py4j/java_gateway.py", line 1224, in send_command
    raise Py4JNetworkError("Answer from Java side is empty")
py4j.protocol.Py4JNetworkError: Answer from Java side is empty

During handling of the above exception, another exception occurred:

Traceback (most recent call last):
  File "/usr/local/lib/python3.8/dist-packages/py4j/java_gateway.py", line 1038, in send_command
    response = connection.send_command(command)
  File "/usr/local/lib/python3.8/dist-packages/py4j/java_gateway.py", line 1228, in send_command
    raise Py4JNetworkError(
py4j.protocol.Py4JNetworkError: Error while receiving
ERROR:root:Exception while sending command.
Traceback (most recent call last):
  File "/usr/local/lib/python3.8/dist-packages/py4j/java_gateway.py", line 1224, in send_command
    raise Py4JNetworkError("Answer from Java side is empty")
py4j.protocol.Py4JNetworkError: Answer from Java side is empty

During handling of the above exception, another exception occurred:

Traceback (most recent call last):
  File "/usr/local/lib/python3.8/dist-packages/py4j/java_gateway.py", line 1038, in send_command
    response = connection.send_command(command)
  File "/usr/local/lib/python3.8/dist-packages/py4j/java_gateway.py", line 1228, in send_command
    raise Py4JNetworkError(
py4j.protocol.Py4JNetworkError: Error while receiving
ERROR:root:Exception while sending command.
Traceback (most recent call last):
  File "/usr/local/lib/python3.8/dist-packages/py4j/java_gateway.py", line 1224, in send_command
    raise Py4JNetworkError("Answer from Java side is empty")
py4j.protocol.Py4JNetworkError: Answer from Java side is empty

During handling of the above exception, another exception occurred:

Traceback (most recent call last):
  File "/usr/local/lib/python3.8/dist-packages/py4j/java_gateway.py", line 1038, in send_command
    response = connection.send_command(command)
  File "/usr/local/lib/python3.8/dist-packages/py4j/java_gateway.py", line 1228, in send_command
    raise Py4JNetworkError(
py4j.protocol.Py4JNetworkError: Error while receiving
ERROR:root:Exception while sending command.
Traceback (most recent call last):
  File "/usr/local/lib/python3.8/dist-packages/py4j/java_gateway.py", line 1224, in send_command
    raise Py4JNetworkError("Answer from Java side is empty")
py4j.protocol.Py4JNetworkError: Answer from Java side is empty

During handling of the above exception, another exception occurred:

Traceback (most recent call last):
  File "/usr/local/lib/python3.8/dist-packages/py4j/java_gateway.py", line 1038, in send_command
    response = connection.send_command(command)
  File "/usr/local/lib/python3.8/dist-packages/py4j/java_gateway.py", line 1228, in send_command
    raise Py4JNetworkError(
py4j.protocol.Py4JNetworkError: Error while receiving
ERROR:root:Exception while sending command.
Traceback (most recent call last):
  File "/usr/local/lib/python3.8/dist-packages/py4j/java_gateway.py", line 1224, in send_command
    raise Py4JNetworkError("Answer from Java side is empty")
py4j.protocol.Py4JNetworkError: Answer from Java side is empty

During handling of the above exception, another exception occurred:

Traceback (most recent call last):
  File "/usr/local/lib/python3.8/dist-packages/py4j/java_gateway.py", line 1038, in send_command
    response = connection.send_command(command)
  File "/usr/local/lib/python3.8/dist-packages/py4j/java_gateway.py", line 1228, in send_command
    raise Py4JNetworkError(
py4j.protocol.Py4JNetworkError: Error while receiving
ERROR:root:Exception while sending command.
Traceback (most recent call last):
  File "/usr/local/lib/python3.8/dist-packages/py4j/java_gateway.py", line 1224, in send_command
    raise Py4JNetworkError("Answer from Java side is empty")
py4j.protocol.Py4JNetworkError: Answer from Java side is empty

During handling of the above exception, another exception occurred:

Traceback (most recent call last):
  File "/usr/local/lib/python3.8/dist-packages/py4j/java_gateway.py", line 1038, in send_command
    response = connection.send_command(command)
  File "/usr/local/lib/python3.8/dist-packages/py4j/java_gateway.py", line 1228, in send_command
    raise Py4JNetworkError(
py4j.protocol.Py4JNetworkError: Error while receiving
ERROR:root:Exception while sending command.
Traceback (most recent call last):
  File "/usr/local/lib/python3.8/dist-packages/py4j/java_gateway.py", line 1224, in send_command
    raise Py4JNetworkError("Answer from Java side is empty")
py4j.protocol.Py4JNetworkError: Answer from Java side is empty

During handling of the above exception, another exception occurred:

Traceback (most recent call last):
  File "/usr/local/lib/python3.8/dist-packages/py4j/java_gateway.py", line 1038, in send_command
    response = connection.send_command(command)
  File "/usr/local/lib/python3.8/dist-packages/py4j/java_gateway.py", line 1228, in send_command
    raise Py4JNetworkError(
py4j.protocol.Py4JNetworkError: Error while receiving
ERROR:root:Exception while sending command.
Traceback (most recent call last):
  File "/usr/local/lib/python3.8/dist-packages/py4j/java_gateway.py", line 1224, in send_command
    raise Py4JNetworkError("Answer from Java side is empty")
py4j.protocol.Py4JNetworkError: Answer from Java side is empty

During handling of the above exception, another exception occurred:

Traceback (most recent call last):
  File "/usr/local/lib/python3.8/dist-packages/py4j/java_gateway.py", line 1038, in send_command
    response = connection.send_command(command)
  File "/usr/local/lib/python3.8/dist-packages/py4j/java_gateway.py", line 1228, in send_command
    raise Py4JNetworkError(
py4j.protocol.Py4JNetworkError: Error while receiving
ERROR:root:Exception while sending command.
Traceback (most recent call last):
  File "/usr/local/lib/python3.8/dist-packages/py4j/java_gateway.py", line 1224, in send_command
    raise Py4JNetworkError("Answer from Java side is empty")
py4j.protocol.Py4JNetworkError: Answer from Java side is empty

During handling of the above exception, another exception occurred:

Traceback (most recent call last):
  File "/usr/local/lib/python3.8/dist-packages/py4j/java_gateway.py", line 1038, in send_command
    response = connection.send_command(command)
  File "/usr/local/lib/python3.8/dist-packages/py4j/java_gateway.py", line 1228, in send_command
    raise Py4JNetworkError(
py4j.protocol.Py4JNetworkError: Error while receiving
ERROR:root:Exception while sending command.
Traceback (most recent call last):
  File "/usr/local/lib/python3.8/dist-packages/py4j/java_gateway.py", line 1224, in send_command
    raise Py4JNetworkError("Answer from Java side is empty")
py4j.protocol.Py4JNetworkError: Answer from Java side is empty

During handling of the above exception, another exception occurred:

Traceback (most recent call last):
  File "/usr/local/lib/python3.8/dist-packages/py4j/java_gateway.py", line 1038, in send_command
    response = connection.send_command(command)
  File "/usr/local/lib/python3.8/dist-packages/py4j/java_gateway.py", line 1228, in send_command
    raise Py4JNetworkError(
py4j.protocol.Py4JNetworkError: Error while receiving
ERROR:root:Exception while sending command.
Traceback (most recent call last):
  File "/usr/local/lib/python3.8/dist-packages/py4j/java_gateway.py", line 1224, in send_command
    raise Py4JNetworkError("Answer from Java side is empty")
py4j.protocol.Py4JNetworkError: Answer from Java side is empty

During handling of the above exception, another exception occurred:

Traceback (most recent call last):
  File "/usr/local/lib/python3.8/dist-packages/py4j/java_gateway.py", line 1038, in send_command
    response = connection.send_command(command)
  File "/usr/local/lib/python3.8/dist-packages/py4j/java_gateway.py", line 1228, in send_command
    raise Py4JNetworkError(
py4j.protocol.Py4JNetworkError: Error while receiving
ERROR:root:Exception while sending command.
Traceback (most recent call last):
  File "/usr/local/lib/python3.8/dist-packages/py4j/java_gateway.py", line 1224, in send_command
    raise Py4JNetworkError("Answer from Java side is empty")
py4j.protocol.Py4JNetworkError: Answer from Java side is empty

During handling of the above exception, another exception occurred:

Traceback (most recent call last):
  File "/usr/local/lib/python3.8/dist-packages/py4j/java_gateway.py", line 1038, in send_command
    response = connection.send_command(command)
  File "/usr/local/lib/python3.8/dist-packages/py4j/java_gateway.py", line 1228, in send_command
    raise Py4JNetworkError(
py4j.protocol.Py4JNetworkError: Error while receiving
ERROR:root:Exception while sending command.
Traceback (most recent call last):
  File "/usr/local/lib/python3.8/dist-packages/py4j/java_gateway.py", line 1224, in send_command
    raise Py4JNetworkError("Answer from Java side is empty")
py4j.protocol.Py4JNetworkError: Answer from Java side is empty

During handling of the above exception, another exception occurred:

Traceback (most recent call last):
  File "/usr/local/lib/python3.8/dist-packages/py4j/java_gateway.py", line 1038, in send_command
    response = connection.send_command(command)
  File "/usr/local/lib/python3.8/dist-packages/py4j/java_gateway.py", line 1228, in send_command
    raise Py4JNetworkError(
py4j.protocol.Py4JNetworkError: Error while receiving
ERROR:root:Exception while sending command.
Traceback (most recent call last):
  File "/usr/local/lib/python3.8/dist-packages/py4j/java_gateway.py", line 1224, in send_command
    raise Py4JNetworkError("Answer from Java side is empty")
py4j.protocol.Py4JNetworkError: Answer from Java side is empty

During handling of the above exception, another exception occurred:

Traceback (most recent call last):
  File "/usr/local/lib/python3.8/dist-packages/py4j/java_gateway.py", line 1038, in send_command
    response = connection.send_command(command)
  File "/usr/local/lib/python3.8/dist-packages/py4j/java_gateway.py", line 1228, in send_command
    raise Py4JNetworkError(
py4j.protocol.Py4JNetworkError: Error while receiving
ERROR:root:Exception while sending command.
Traceback (most recent call last):
  File "/usr/local/lib/python3.8/dist-packages/py4j/java_gateway.py", line 1224, in send_command
    raise Py4JNetworkError("Answer from Java side is empty")
py4j.protocol.Py4JNetworkError: Answer from Java side is empty

During handling of the above exception, another exception occurred:

Traceback (most recent call last):
  File "/usr/local/lib/python3.8/dist-packages/py4j/java_gateway.py", line 1038, in send_command
    response = connection.send_command(command)
  File "/usr/local/lib/python3.8/dist-packages/py4j/java_gateway.py", line 1228, in send_command
    raise Py4JNetworkError(
py4j.protocol.Py4JNetworkError: Error while receiving
ERROR:py4j.java_gateway:There was an exception while executing the Python Proxy on the Python Side.
Traceback (most recent call last):
  File "/usr/local/lib/python3.8/dist-packages/py4j/java_gateway.py", line 2463, in _call_proxy
    return_value = getattr(self.pool[obj_id], method)(*params)
  File "/app/myenv/gym_ai.py", line 111, in processing
    request = self.pipe.recv()
  File "/usr/lib/python3.8/multiprocessing/connection.py", line 250, in recv
    buf = self._recv_bytes()
  File "/usr/lib/python3.8/multiprocessing/connection.py", line 414, in _recv_bytes
    buf = self._recv(4)
  File "/usr/lib/python3.8/multiprocessing/connection.py", line 383, in _recv
    raise EOFError
EOFError
ERROR:root:Exception while sending command.
Traceback (most recent call last):
  File "/usr/local/lib/python3.8/dist-packages/py4j/java_gateway.py", line 1224, in send_command
    raise Py4JNetworkError("Answer from Java side is empty")
py4j.protocol.Py4JNetworkError: Answer from Java side is empty

During handling of the above exception, another exception occurred:

Traceback (most recent call last):
  File "/usr/local/lib/python3.8/dist-packages/py4j/java_gateway.py", line 1038, in send_command
    response = connection.send_command(command)
  File "/usr/local/lib/python3.8/dist-packages/py4j/java_gateway.py", line 1228, in send_command
    raise Py4JNetworkError(
py4j.protocol.Py4JNetworkError: Error while receiving
ERROR:root:Exception while sending command.
Traceback (most recent call last):
  File "/usr/local/lib/python3.8/dist-packages/py4j/java_gateway.py", line 1224, in send_command
    raise Py4JNetworkError("Answer from Java side is empty")
py4j.protocol.Py4JNetworkError: Answer from Java side is empty

During handling of the above exception, another exception occurred:

Traceback (most recent call last):
  File "/usr/local/lib/python3.8/dist-packages/py4j/java_gateway.py", line 1038, in send_command
    response = connection.send_command(command)
  File "/usr/local/lib/python3.8/dist-packages/py4j/java_gateway.py", line 1228, in send_command
    raise Py4JNetworkError(
py4j.protocol.Py4JNetworkError: Error while receiving
ERROR:root:Exception while sending command.
Traceback (most recent call last):
  File "/usr/local/lib/python3.8/dist-packages/py4j/java_gateway.py", line 1224, in send_command
    raise Py4JNetworkError("Answer from Java side is empty")
py4j.protocol.Py4JNetworkError: Answer from Java side is empty

During handling of the above exception, another exception occurred:

Traceback (most recent call last):
  File "/usr/local/lib/python3.8/dist-packages/py4j/java_gateway.py", line 1038, in send_command
    response = connection.send_command(command)
  File "/usr/local/lib/python3.8/dist-packages/py4j/java_gateway.py", line 1228, in send_command
    raise Py4JNetworkError(
py4j.protocol.Py4JNetworkError: Error while receiving
ERROR:root:Exception while sending command.
Traceback (most recent call last):
  File "/usr/local/lib/python3.8/dist-packages/py4j/java_gateway.py", line 1224, in send_command
    raise Py4JNetworkError("Answer from Java side is empty")
py4j.protocol.Py4JNetworkError: Answer from Java side is empty

During handling of the above exception, another exception occurred:

Traceback (most recent call last):
  File "/usr/local/lib/python3.8/dist-packages/py4j/java_gateway.py", line 1038, in send_command
    response = connection.send_command(command)
  File "/usr/local/lib/python3.8/dist-packages/py4j/java_gateway.py", line 1228, in send_command
    raise Py4JNetworkError(
py4j.protocol.Py4JNetworkError: Error while receiving
ERROR:root:Exception while sending command.
Traceback (most recent call last):
  File "/usr/local/lib/python3.8/dist-packages/py4j/java_gateway.py", line 1224, in send_command
    raise Py4JNetworkError("Answer from Java side is empty")
py4j.protocol.Py4JNetworkError: Answer from Java side is empty

During handling of the above exception, another exception occurred:

Traceback (most recent call last):
  File "/usr/local/lib/python3.8/dist-packages/py4j/java_gateway.py", line 1038, in send_command
    response = connection.send_command(command)
  File "/usr/local/lib/python3.8/dist-packages/py4j/java_gateway.py", line 1228, in send_command
    raise Py4JNetworkError(
py4j.protocol.Py4JNetworkError: Error while receiving
ERROR:root:Exception while sending command.
Traceback (most recent call last):
  File "/usr/local/lib/python3.8/dist-packages/py4j/java_gateway.py", line 1224, in send_command
    raise Py4JNetworkError("Answer from Java side is empty")
py4j.protocol.Py4JNetworkError: Answer from Java side is empty

During handling of the above exception, another exception occurred:

Traceback (most recent call last):
  File "/usr/local/lib/python3.8/dist-packages/py4j/java_gateway.py", line 1038, in send_command
    response = connection.send_command(command)
  File "/usr/local/lib/python3.8/dist-packages/py4j/java_gateway.py", line 1228, in send_command
    raise Py4JNetworkError(
py4j.protocol.Py4JNetworkError: Error while receiving
ERROR:root:Exception while sending command.
Traceback (most recent call last):
  File "/usr/local/lib/python3.8/dist-packages/py4j/java_gateway.py", line 1224, in send_command
    raise Py4JNetworkError("Answer from Java side is empty")
py4j.protocol.Py4JNetworkError: Answer from Java side is empty

During handling of the above exception, another exception occurred:

Traceback (most recent call last):
  File "/usr/local/lib/python3.8/dist-packages/py4j/java_gateway.py", line 1038, in send_command
    response = connection.send_command(command)
  File "/usr/local/lib/python3.8/dist-packages/py4j/java_gateway.py", line 1228, in send_command
    raise Py4JNetworkError(
py4j.protocol.Py4JNetworkError: Error while receiving
ERROR:root:Exception while sending command.
Traceback (most recent call last):
  File "/usr/local/lib/python3.8/dist-packages/py4j/java_gateway.py", line 1224, in send_command
    raise Py4JNetworkError("Answer from Java side is empty")
py4j.protocol.Py4JNetworkError: Answer from Java side is empty

During handling of the above exception, another exception occurred:

Traceback (most recent call last):
  File "/usr/local/lib/python3.8/dist-packages/py4j/java_gateway.py", line 1038, in send_command
    response = connection.send_command(command)
  File "/usr/local/lib/python3.8/dist-packages/py4j/java_gateway.py", line 1228, in send_command
    raise Py4JNetworkError(
py4j.protocol.Py4JNetworkError: Error while receiving
ERROR:root:Exception while sending command.
Traceback (most recent call last):
  File "/usr/local/lib/python3.8/dist-packages/py4j/java_gateway.py", line 1224, in send_command
    raise Py4JNetworkError("Answer from Java side is empty")
py4j.protocol.Py4JNetworkError: Answer from Java side is empty

During handling of the above exception, another exception occurred:

Traceback (most recent call last):
  File "/usr/local/lib/python3.8/dist-packages/py4j/java_gateway.py", line 1038, in send_command
    response = connection.send_command(command)
  File "/usr/local/lib/python3.8/dist-packages/py4j/java_gateway.py", line 1228, in send_command
    raise Py4JNetworkError(
py4j.protocol.Py4JNetworkError: Error while receiving
ERROR:root:Exception while sending command.
Traceback (most recent call last):
  File "/usr/local/lib/python3.8/dist-packages/py4j/java_gateway.py", line 1224, in send_command
    raise Py4JNetworkError("Answer from Java side is empty")
py4j.protocol.Py4JNetworkError: Answer from Java side is empty

During handling of the above exception, another exception occurred:

Traceback (most recent call last):
  File "/usr/local/lib/python3.8/dist-packages/py4j/java_gateway.py", line 1038, in send_command
    response = connection.send_command(command)
  File "/usr/local/lib/python3.8/dist-packages/py4j/java_gateway.py", line 1228, in send_command
    raise Py4JNetworkError(
py4j.protocol.Py4JNetworkError: Error while receiving
ERROR:root:Exception while sending command.
Traceback (most recent call last):
  File "/usr/local/lib/python3.8/dist-packages/py4j/java_gateway.py", line 1224, in send_command
    raise Py4JNetworkError("Answer from Java side is empty")
py4j.protocol.Py4JNetworkError: Answer from Java side is empty

During handling of the above exception, another exception occurred:

Traceback (most recent call last):
  File "/usr/local/lib/python3.8/dist-packages/py4j/java_gateway.py", line 1038, in send_command
    response = connection.send_command(command)
  File "/usr/local/lib/python3.8/dist-packages/py4j/java_gateway.py", line 1228, in send_command
    raise Py4JNetworkError(
py4j.protocol.Py4JNetworkError: Error while receiving
ERROR:root:Exception while sending command.
Traceback (most recent call last):
  File "/usr/local/lib/python3.8/dist-packages/py4j/java_gateway.py", line 1224, in send_command
    raise Py4JNetworkError("Answer from Java side is empty")
py4j.protocol.Py4JNetworkError: Answer from Java side is empty

During handling of the above exception, another exception occurred:

Traceback (most recent call last):
  File "/usr/local/lib/python3.8/dist-packages/py4j/java_gateway.py", line 1038, in send_command
    response = connection.send_command(command)
  File "/usr/local/lib/python3.8/dist-packages/py4j/java_gateway.py", line 1228, in send_command
    raise Py4JNetworkError(
py4j.protocol.Py4JNetworkError: Error while receiving
ERROR:root:Exception while sending command.
Traceback (most recent call last):
  File "/usr/local/lib/python3.8/dist-packages/py4j/java_gateway.py", line 1224, in send_command
    raise Py4JNetworkError("Answer from Java side is empty")
py4j.protocol.Py4JNetworkError: Answer from Java side is empty

During handling of the above exception, another exception occurred:

Traceback (most recent call last):
  File "/usr/local/lib/python3.8/dist-packages/py4j/java_gateway.py", line 1038, in send_command
    response = connection.send_command(command)
  File "/usr/local/lib/python3.8/dist-packages/py4j/java_gateway.py", line 1228, in send_command
    raise Py4JNetworkError(
py4j.protocol.Py4JNetworkError: Error while receiving
ERROR:root:Exception while sending command.
Traceback (most recent call last):
  File "/usr/local/lib/python3.8/dist-packages/py4j/java_gateway.py", line 1224, in send_command
    raise Py4JNetworkError("Answer from Java side is empty")
py4j.protocol.Py4JNetworkError: Answer from Java side is empty

During handling of the above exception, another exception occurred:

Traceback (most recent call last):
  File "/usr/local/lib/python3.8/dist-packages/py4j/java_gateway.py", line 1038, in send_command
    response = connection.send_command(command)
  File "/usr/local/lib/python3.8/dist-packages/py4j/java_gateway.py", line 1228, in send_command
    raise Py4JNetworkError(
py4j.protocol.Py4JNetworkError: Error while receiving
ERROR:root:Exception while sending command.
Traceback (most recent call last):
  File "/usr/local/lib/python3.8/dist-packages/py4j/java_gateway.py", line 1224, in send_command
    raise Py4JNetworkError("Answer from Java side is empty")
py4j.protocol.Py4JNetworkError: Answer from Java side is empty

During handling of the above exception, another exception occurred:

Traceback (most recent call last):
  File "/usr/local/lib/python3.8/dist-packages/py4j/java_gateway.py", line 1038, in send_command
    response = connection.send_command(command)
  File "/usr/local/lib/python3.8/dist-packages/py4j/java_gateway.py", line 1228, in send_command
    raise Py4JNetworkError(
py4j.protocol.Py4JNetworkError: Error while receiving
ERROR:root:Exception while sending command.
Traceback (most recent call last):
  File "/usr/local/lib/python3.8/dist-packages/py4j/java_gateway.py", line 1224, in send_command
    raise Py4JNetworkError("Answer from Java side is empty")
py4j.protocol.Py4JNetworkError: Answer from Java side is empty

During handling of the above exception, another exception occurred:

Traceback (most recent call last):
  File "/usr/local/lib/python3.8/dist-packages/py4j/java_gateway.py", line 1038, in send_command
    response = connection.send_command(command)
  File "/usr/local/lib/python3.8/dist-packages/py4j/java_gateway.py", line 1228, in send_command
    raise Py4JNetworkError(
py4j.protocol.Py4JNetworkError: Error while receiving
ERROR:root:Exception while sending command.
Traceback (most recent call last):
  File "/usr/local/lib/python3.8/dist-packages/py4j/java_gateway.py", line 1224, in send_command
    raise Py4JNetworkError("Answer from Java side is empty")
py4j.protocol.Py4JNetworkError: Answer from Java side is empty

During handling of the above exception, another exception occurred:

Traceback (most recent call last):
  File "/usr/local/lib/python3.8/dist-packages/py4j/java_gateway.py", line 1038, in send_command
    response = connection.send_command(command)
  File "/usr/local/lib/python3.8/dist-packages/py4j/java_gateway.py", line 1228, in send_command
    raise Py4JNetworkError(
py4j.protocol.Py4JNetworkError: Error while receiving
ERROR:py4j.java_gateway:There was an exception while executing the Python Proxy on the Python Side.
Traceback (most recent call last):
  File "/usr/local/lib/python3.8/dist-packages/py4j/java_gateway.py", line 2463, in _call_proxy
    return_value = getattr(self.pool[obj_id], method)(*params)
  File "/app/myenv/gym_ai.py", line 111, in processing
    request = self.pipe.recv()
  File "/usr/lib/python3.8/multiprocessing/connection.py", line 250, in recv
    buf = self._recv_bytes()
  File "/usr/lib/python3.8/multiprocessing/connection.py", line 414, in _recv_bytes
    buf = self._recv(4)
  File "/usr/lib/python3.8/multiprocessing/connection.py", line 383, in _recv
    raise EOFError
EOFError
ERROR:root:Exception while sending command.
Traceback (most recent call last):
  File "/usr/local/lib/python3.8/dist-packages/py4j/java_gateway.py", line 1224, in send_command
    raise Py4JNetworkError("Answer from Java side is empty")
py4j.protocol.Py4JNetworkError: Answer from Java side is empty

During handling of the above exception, another exception occurred:

Traceback (most recent call last):
  File "/usr/local/lib/python3.8/dist-packages/py4j/java_gateway.py", line 1038, in send_command
    response = connection.send_command(command)
  File "/usr/local/lib/python3.8/dist-packages/py4j/java_gateway.py", line 1228, in send_command
    raise Py4JNetworkError(
py4j.protocol.Py4JNetworkError: Error while receiving
ERROR:root:Exception while sending command.
Traceback (most recent call last):
  File "/usr/local/lib/python3.8/dist-packages/py4j/java_gateway.py", line 1224, in send_command
    raise Py4JNetworkError("Answer from Java side is empty")
py4j.protocol.Py4JNetworkError: Answer from Java side is empty

During handling of the above exception, another exception occurred:

Traceback (most recent call last):
  File "/usr/local/lib/python3.8/dist-packages/py4j/java_gateway.py", line 1038, in send_command
    response = connection.send_command(command)
  File "/usr/local/lib/python3.8/dist-packages/py4j/java_gateway.py", line 1228, in send_command
    raise Py4JNetworkError(
py4j.protocol.Py4JNetworkError: Error while receiving
ERROR:root:Exception while sending command.
Traceback (most recent call last):
  File "/usr/local/lib/python3.8/dist-packages/py4j/java_gateway.py", line 1224, in send_command
    raise Py4JNetworkError("Answer from Java side is empty")
py4j.protocol.Py4JNetworkError: Answer from Java side is empty

During handling of the above exception, another exception occurred:

Traceback (most recent call last):
  File "/usr/local/lib/python3.8/dist-packages/py4j/java_gateway.py", line 1038, in send_command
    response = connection.send_command(command)
  File "/usr/local/lib/python3.8/dist-packages/py4j/java_gateway.py", line 1228, in send_command
    raise Py4JNetworkError(
py4j.protocol.Py4JNetworkError: Error while receiving
ERROR:root:Exception while sending command.
Traceback (most recent call last):
  File "/usr/local/lib/python3.8/dist-packages/py4j/java_gateway.py", line 1224, in send_command
    raise Py4JNetworkError("Answer from Java side is empty")
py4j.protocol.Py4JNetworkError: Answer from Java side is empty

During handling of the above exception, another exception occurred:

Traceback (most recent call last):
  File "/usr/local/lib/python3.8/dist-packages/py4j/java_gateway.py", line 1038, in send_command
    response = connection.send_command(command)
  File "/usr/local/lib/python3.8/dist-packages/py4j/java_gateway.py", line 1228, in send_command
    raise Py4JNetworkError(
py4j.protocol.Py4JNetworkError: Error while receiving
ERROR:root:Exception while sending command.
Traceback (most recent call last):
  File "/usr/local/lib/python3.8/dist-packages/py4j/java_gateway.py", line 1224, in send_command
    raise Py4JNetworkError("Answer from Java side is empty")
py4j.protocol.Py4JNetworkError: Answer from Java side is empty

During handling of the above exception, another exception occurred:

Traceback (most recent call last):
  File "/usr/local/lib/python3.8/dist-packages/py4j/java_gateway.py", line 1038, in send_command
    response = connection.send_command(command)
  File "/usr/local/lib/python3.8/dist-packages/py4j/java_gateway.py", line 1228, in send_command
    raise Py4JNetworkError(
py4j.protocol.Py4JNetworkError: Error while receiving
ERROR:root:Exception while sending command.
Traceback (most recent call last):
  File "/usr/local/lib/python3.8/dist-packages/py4j/java_gateway.py", line 1224, in send_command
    raise Py4JNetworkError("Answer from Java side is empty")
py4j.protocol.Py4JNetworkError: Answer from Java side is empty

During handling of the above exception, another exception occurred:

Traceback (most recent call last):
  File "/usr/local/lib/python3.8/dist-packages/py4j/java_gateway.py", line 1038, in send_command
    response = connection.send_command(command)
  File "/usr/local/lib/python3.8/dist-packages/py4j/java_gateway.py", line 1228, in send_command
    raise Py4JNetworkError(
py4j.protocol.Py4JNetworkError: Error while receiving
ERROR:root:Exception while sending command.
Traceback (most recent call last):
  File "/usr/local/lib/python3.8/dist-packages/py4j/java_gateway.py", line 1224, in send_command
    raise Py4JNetworkError("Answer from Java side is empty")
py4j.protocol.Py4JNetworkError: Answer from Java side is empty

During handling of the above exception, another exception occurred:

Traceback (most recent call last):
  File "/usr/local/lib/python3.8/dist-packages/py4j/java_gateway.py", line 1038, in send_command
    response = connection.send_command(command)
  File "/usr/local/lib/python3.8/dist-packages/py4j/java_gateway.py", line 1228, in send_command
    raise Py4JNetworkError(
py4j.protocol.Py4JNetworkError: Error while receiving
ERROR:root:Exception while sending command.
Traceback (most recent call last):
  File "/usr/local/lib/python3.8/dist-packages/py4j/java_gateway.py", line 1224, in send_command
    raise Py4JNetworkError("Answer from Java side is empty")
py4j.protocol.Py4JNetworkError: Answer from Java side is empty

During handling of the above exception, another exception occurred:

Traceback (most recent call last):
  File "/usr/local/lib/python3.8/dist-packages/py4j/java_gateway.py", line 1038, in send_command
    response = connection.send_command(command)
  File "/usr/local/lib/python3.8/dist-packages/py4j/java_gateway.py", line 1228, in send_command
    raise Py4JNetworkError(
py4j.protocol.Py4JNetworkError: Error while receiving
ERROR:root:Exception while sending command.
Traceback (most recent call last):
  File "/usr/local/lib/python3.8/dist-packages/py4j/java_gateway.py", line 1224, in send_command
    raise Py4JNetworkError("Answer from Java side is empty")
py4j.protocol.Py4JNetworkError: Answer from Java side is empty

During handling of the above exception, another exception occurred:

Traceback (most recent call last):
  File "/usr/local/lib/python3.8/dist-packages/py4j/java_gateway.py", line 1038, in send_command
    response = connection.send_command(command)
  File "/usr/local/lib/python3.8/dist-packages/py4j/java_gateway.py", line 1228, in send_command
    raise Py4JNetworkError(
py4j.protocol.Py4JNetworkError: Error while receiving
ERROR:root:Exception while sending command.
Traceback (most recent call last):
  File "/usr/local/lib/python3.8/dist-packages/py4j/java_gateway.py", line 1224, in send_command
    raise Py4JNetworkError("Answer from Java side is empty")
py4j.protocol.Py4JNetworkError: Answer from Java side is empty

During handling of the above exception, another exception occurred:

Traceback (most recent call last):
  File "/usr/local/lib/python3.8/dist-packages/py4j/java_gateway.py", line 1038, in send_command
    response = connection.send_command(command)
  File "/usr/local/lib/python3.8/dist-packages/py4j/java_gateway.py", line 1228, in send_command
    raise Py4JNetworkError(
py4j.protocol.Py4JNetworkError: Error while receiving
ERROR:root:Exception while sending command.
Traceback (most recent call last):
  File "/usr/local/lib/python3.8/dist-packages/py4j/java_gateway.py", line 1224, in send_command
    raise Py4JNetworkError("Answer from Java side is empty")
py4j.protocol.Py4JNetworkError: Answer from Java side is empty

During handling of the above exception, another exception occurred:

Traceback (most recent call last):
  File "/usr/local/lib/python3.8/dist-packages/py4j/java_gateway.py", line 1038, in send_command
    response = connection.send_command(command)
  File "/usr/local/lib/python3.8/dist-packages/py4j/java_gateway.py", line 1228, in send_command
    raise Py4JNetworkError(
py4j.protocol.Py4JNetworkError: Error while receiving
ERROR:root:Exception while sending command.
Traceback (most recent call last):
  File "/usr/local/lib/python3.8/dist-packages/py4j/java_gateway.py", line 1224, in send_command
    raise Py4JNetworkError("Answer from Java side is empty")
py4j.protocol.Py4JNetworkError: Answer from Java side is empty

During handling of the above exception, another exception occurred:

Traceback (most recent call last):
  File "/usr/local/lib/python3.8/dist-packages/py4j/java_gateway.py", line 1038, in send_command
    response = connection.send_command(command)
  File "/usr/local/lib/python3.8/dist-packages/py4j/java_gateway.py", line 1228, in send_command
    raise Py4JNetworkError(
py4j.protocol.Py4JNetworkError: Error while receiving
ERROR:root:Exception while sending command.
Traceback (most recent call last):
  File "/usr/local/lib/python3.8/dist-packages/py4j/java_gateway.py", line 1224, in send_command
    raise Py4JNetworkError("Answer from Java side is empty")
py4j.protocol.Py4JNetworkError: Answer from Java side is empty

During handling of the above exception, another exception occurred:

Traceback (most recent call last):
  File "/usr/local/lib/python3.8/dist-packages/py4j/java_gateway.py", line 1038, in send_command
    response = connection.send_command(command)
  File "/usr/local/lib/python3.8/dist-packages/py4j/java_gateway.py", line 1228, in send_command
    raise Py4JNetworkError(
py4j.protocol.Py4JNetworkError: Error while receiving
ERROR:py4j.java_gateway:There was an exception while executing the Python Proxy on the Python Side.
Traceback (most recent call last):
  File "/usr/local/lib/python3.8/dist-packages/py4j/java_gateway.py", line 2463, in _call_proxy
    return_value = getattr(self.pool[obj_id], method)(*params)
  File "/app/myenv/gym_ai.py", line 111, in processing
    request = self.pipe.recv()
  File "/usr/lib/python3.8/multiprocessing/connection.py", line 250, in recv
    buf = self._recv_bytes()
  File "/usr/lib/python3.8/multiprocessing/connection.py", line 414, in _recv_bytes
    buf = self._recv(4)
  File "/usr/lib/python3.8/multiprocessing/connection.py", line 383, in _recv
    raise EOFError
EOFError
ERROR:root:Exception while sending command.
Traceback (most recent call last):
  File "/usr/local/lib/python3.8/dist-packages/py4j/java_gateway.py", line 1224, in send_command
    raise Py4JNetworkError("Answer from Java side is empty")
py4j.protocol.Py4JNetworkError: Answer from Java side is empty

During handling of the above exception, another exception occurred:

Traceback (most recent call last):
  File "/usr/local/lib/python3.8/dist-packages/py4j/java_gateway.py", line 1038, in send_command
    response = connection.send_command(command)
  File "/usr/local/lib/python3.8/dist-packages/py4j/java_gateway.py", line 1228, in send_command
    raise Py4JNetworkError(
py4j.protocol.Py4JNetworkError: Error while receiving
ERROR:root:Exception while sending command.
Traceback (most recent call last):
  File "/usr/local/lib/python3.8/dist-packages/py4j/java_gateway.py", line 1224, in send_command
    raise Py4JNetworkError("Answer from Java side is empty")
py4j.protocol.Py4JNetworkError: Answer from Java side is empty

During handling of the above exception, another exception occurred:

Traceback (most recent call last):
  File "/usr/local/lib/python3.8/dist-packages/py4j/java_gateway.py", line 1038, in send_command
    response = connection.send_command(command)
  File "/usr/local/lib/python3.8/dist-packages/py4j/java_gateway.py", line 1228, in send_command
    raise Py4JNetworkError(
py4j.protocol.Py4JNetworkError: Error while receiving
ERROR:root:Exception while sending command.
Traceback (most recent call last):
  File "/usr/local/lib/python3.8/dist-packages/py4j/java_gateway.py", line 1224, in send_command
    raise Py4JNetworkError("Answer from Java side is empty")
py4j.protocol.Py4JNetworkError: Answer from Java side is empty

During handling of the above exception, another exception occurred:

Traceback (most recent call last):
  File "/usr/local/lib/python3.8/dist-packages/py4j/java_gateway.py", line 1038, in send_command
    response = connection.send_command(command)
  File "/usr/local/lib/python3.8/dist-packages/py4j/java_gateway.py", line 1228, in send_command
    raise Py4JNetworkError(
py4j.protocol.Py4JNetworkError: Error while receiving
ERROR:root:Exception while sending command.
Traceback (most recent call last):
  File "/usr/local/lib/python3.8/dist-packages/py4j/java_gateway.py", line 1224, in send_command
    raise Py4JNetworkError("Answer from Java side is empty")
py4j.protocol.Py4JNetworkError: Answer from Java side is empty

During handling of the above exception, another exception occurred:

Traceback (most recent call last):
  File "/usr/local/lib/python3.8/dist-packages/py4j/java_gateway.py", line 1038, in send_command
    response = connection.send_command(command)
  File "/usr/local/lib/python3.8/dist-packages/py4j/java_gateway.py", line 1228, in send_command
    raise Py4JNetworkError(
py4j.protocol.Py4JNetworkError: Error while receiving
ERROR:root:Exception while sending command.
Traceback (most recent call last):
  File "/usr/local/lib/python3.8/dist-packages/py4j/java_gateway.py", line 1224, in send_command
    raise Py4JNetworkError("Answer from Java side is empty")
py4j.protocol.Py4JNetworkError: Answer from Java side is empty

During handling of the above exception, another exception occurred:

Traceback (most recent call last):
  File "/usr/local/lib/python3.8/dist-packages/py4j/java_gateway.py", line 1038, in send_command
    response = connection.send_command(command)
  File "/usr/local/lib/python3.8/dist-packages/py4j/java_gateway.py", line 1228, in send_command
    raise Py4JNetworkError(
py4j.protocol.Py4JNetworkError: Error while receiving
ERROR:root:Exception while sending command.
Traceback (most recent call last):
  File "/usr/local/lib/python3.8/dist-packages/py4j/java_gateway.py", line 1224, in send_command
    raise Py4JNetworkError("Answer from Java side is empty")
py4j.protocol.Py4JNetworkError: Answer from Java side is empty

During handling of the above exception, another exception occurred:

Traceback (most recent call last):
  File "/usr/local/lib/python3.8/dist-packages/py4j/java_gateway.py", line 1038, in send_command
    response = connection.send_command(command)
  File "/usr/local/lib/python3.8/dist-packages/py4j/java_gateway.py", line 1228, in send_command
    raise Py4JNetworkError(
py4j.protocol.Py4JNetworkError: Error while receiving
ERROR:root:Exception while sending command.
Traceback (most recent call last):
  File "/usr/local/lib/python3.8/dist-packages/py4j/java_gateway.py", line 1224, in send_command
    raise Py4JNetworkError("Answer from Java side is empty")
py4j.protocol.Py4JNetworkError: Answer from Java side is empty

During handling of the above exception, another exception occurred:

Traceback (most recent call last):
  File "/usr/local/lib/python3.8/dist-packages/py4j/java_gateway.py", line 1038, in send_command
    response = connection.send_command(command)
  File "/usr/local/lib/python3.8/dist-packages/py4j/java_gateway.py", line 1228, in send_command
    raise Py4JNetworkError(
py4j.protocol.Py4JNetworkError: Error while receiving
ERROR:root:Exception while sending command.
Traceback (most recent call last):
  File "/usr/local/lib/python3.8/dist-packages/py4j/java_gateway.py", line 1224, in send_command
    raise Py4JNetworkError("Answer from Java side is empty")
py4j.protocol.Py4JNetworkError: Answer from Java side is empty

During handling of the above exception, another exception occurred:

Traceback (most recent call last):
  File "/usr/local/lib/python3.8/dist-packages/py4j/java_gateway.py", line 1038, in send_command
    response = connection.send_command(command)
  File "/usr/local/lib/python3.8/dist-packages/py4j/java_gateway.py", line 1228, in send_command
    raise Py4JNetworkError(
py4j.protocol.Py4JNetworkError: Error while receiving
ERROR:root:Exception while sending command.
Traceback (most recent call last):
  File "/usr/local/lib/python3.8/dist-packages/py4j/java_gateway.py", line 1224, in send_command
    raise Py4JNetworkError("Answer from Java side is empty")
py4j.protocol.Py4JNetworkError: Answer from Java side is empty

During handling of the above exception, another exception occurred:

Traceback (most recent call last):
  File "/usr/local/lib/python3.8/dist-packages/py4j/java_gateway.py", line 1038, in send_command
    response = connection.send_command(command)
  File "/usr/local/lib/python3.8/dist-packages/py4j/java_gateway.py", line 1228, in send_command
    raise Py4JNetworkError(
py4j.protocol.Py4JNetworkError: Error while receiving
ERROR:root:Exception while sending command.
Traceback (most recent call last):
  File "/usr/local/lib/python3.8/dist-packages/py4j/java_gateway.py", line 1224, in send_command
    raise Py4JNetworkError("Answer from Java side is empty")
py4j.protocol.Py4JNetworkError: Answer from Java side is empty

During handling of the above exception, another exception occurred:

Traceback (most recent call last):
  File "/usr/local/lib/python3.8/dist-packages/py4j/java_gateway.py", line 1038, in send_command
    response = connection.send_command(command)
  File "/usr/local/lib/python3.8/dist-packages/py4j/java_gateway.py", line 1228, in send_command
    raise Py4JNetworkError(
py4j.protocol.Py4JNetworkError: Error while receiving
ERROR:root:Exception while sending command.
Traceback (most recent call last):
  File "/usr/local/lib/python3.8/dist-packages/py4j/java_gateway.py", line 1224, in send_command
    raise Py4JNetworkError("Answer from Java side is empty")
py4j.protocol.Py4JNetworkError: Answer from Java side is empty

During handling of the above exception, another exception occurred:

Traceback (most recent call last):
  File "/usr/local/lib/python3.8/dist-packages/py4j/java_gateway.py", line 1038, in send_command
    response = connection.send_command(command)
  File "/usr/local/lib/python3.8/dist-packages/py4j/java_gateway.py", line 1228, in send_command
    raise Py4JNetworkError(
py4j.protocol.Py4JNetworkError: Error while receiving
ERROR:root:Exception while sending command.
Traceback (most recent call last):
  File "/usr/local/lib/python3.8/dist-packages/py4j/java_gateway.py", line 1224, in send_command
    raise Py4JNetworkError("Answer from Java side is empty")
py4j.protocol.Py4JNetworkError: Answer from Java side is empty

During handling of the above exception, another exception occurred:

Traceback (most recent call last):
  File "/usr/local/lib/python3.8/dist-packages/py4j/java_gateway.py", line 1038, in send_command
    response = connection.send_command(command)
  File "/usr/local/lib/python3.8/dist-packages/py4j/java_gateway.py", line 1228, in send_command
    raise Py4JNetworkError(
py4j.protocol.Py4JNetworkError: Error while receiving
ERROR:root:Exception while sending command.
Traceback (most recent call last):
  File "/usr/local/lib/python3.8/dist-packages/py4j/java_gateway.py", line 1224, in send_command
    raise Py4JNetworkError("Answer from Java side is empty")
py4j.protocol.Py4JNetworkError: Answer from Java side is empty

During handling of the above exception, another exception occurred:

Traceback (most recent call last):
  File "/usr/local/lib/python3.8/dist-packages/py4j/java_gateway.py", line 1038, in send_command
    response = connection.send_command(command)
  File "/usr/local/lib/python3.8/dist-packages/py4j/java_gateway.py", line 1228, in send_command
    raise Py4JNetworkError(
py4j.protocol.Py4JNetworkError: Error while receiving
ERROR:root:Exception while sending command.
Traceback (most recent call last):
  File "/usr/local/lib/python3.8/dist-packages/py4j/java_gateway.py", line 1224, in send_command
    raise Py4JNetworkError("Answer from Java side is empty")
py4j.protocol.Py4JNetworkError: Answer from Java side is empty

During handling of the above exception, another exception occurred:

Traceback (most recent call last):
  File "/usr/local/lib/python3.8/dist-packages/py4j/java_gateway.py", line 1038, in send_command
    response = connection.send_command(command)
  File "/usr/local/lib/python3.8/dist-packages/py4j/java_gateway.py", line 1228, in send_command
    raise Py4JNetworkError(
py4j.protocol.Py4JNetworkError: Error while receiving
ERROR:root:Exception while sending command.
Traceback (most recent call last):
  File "/usr/local/lib/python3.8/dist-packages/py4j/java_gateway.py", line 1224, in send_command
    raise Py4JNetworkError("Answer from Java side is empty")
py4j.protocol.Py4JNetworkError: Answer from Java side is empty

During handling of the above exception, another exception occurred:

Traceback (most recent call last):
  File "/usr/local/lib/python3.8/dist-packages/py4j/java_gateway.py", line 1038, in send_command
    response = connection.send_command(command)
  File "/usr/local/lib/python3.8/dist-packages/py4j/java_gateway.py", line 1228, in send_command
    raise Py4JNetworkError(
py4j.protocol.Py4JNetworkError: Error while receiving
ERROR:root:Exception while sending command.
Traceback (most recent call last):
  File "/usr/local/lib/python3.8/dist-packages/py4j/java_gateway.py", line 1224, in send_command
    raise Py4JNetworkError("Answer from Java side is empty")
py4j.protocol.Py4JNetworkError: Answer from Java side is empty

During handling of the above exception, another exception occurred:

Traceback (most recent call last):
  File "/usr/local/lib/python3.8/dist-packages/py4j/java_gateway.py", line 1038, in send_command
    response = connection.send_command(command)
  File "/usr/local/lib/python3.8/dist-packages/py4j/java_gateway.py", line 1228, in send_command
    raise Py4JNetworkError(
py4j.protocol.Py4JNetworkError: Error while receiving
ERROR:py4j.java_gateway:There was an exception while executing the Python Proxy on the Python Side.
Traceback (most recent call last):
  File "/usr/local/lib/python3.8/dist-packages/py4j/java_gateway.py", line 2463, in _call_proxy
    return_value = getattr(self.pool[obj_id], method)(*params)
  File "/app/myenv/gym_ai.py", line 111, in processing
    request = self.pipe.recv()
  File "/usr/lib/python3.8/multiprocessing/connection.py", line 250, in recv
    buf = self._recv_bytes()
  File "/usr/lib/python3.8/multiprocessing/connection.py", line 414, in _recv_bytes
    buf = self._recv(4)
  File "/usr/lib/python3.8/multiprocessing/connection.py", line 383, in _recv
    raise EOFError
EOFError
ERROR:root:Exception while sending command.
Traceback (most recent call last):
  File "/usr/local/lib/python3.8/dist-packages/py4j/java_gateway.py", line 1224, in send_command
    raise Py4JNetworkError("Answer from Java side is empty")
py4j.protocol.Py4JNetworkError: Answer from Java side is empty

During handling of the above exception, another exception occurred:

Traceback (most recent call last):
  File "/usr/local/lib/python3.8/dist-packages/py4j/java_gateway.py", line 1038, in send_command
    response = connection.send_command(command)
  File "/usr/local/lib/python3.8/dist-packages/py4j/java_gateway.py", line 1228, in send_command
    raise Py4JNetworkError(
py4j.protocol.Py4JNetworkError: Error while receiving
ERROR:root:Exception while sending command.
Traceback (most recent call last):
  File "/usr/local/lib/python3.8/dist-packages/py4j/java_gateway.py", line 1224, in send_command
    raise Py4JNetworkError("Answer from Java side is empty")
py4j.protocol.Py4JNetworkError: Answer from Java side is empty

During handling of the above exception, another exception occurred:

Traceback (most recent call last):
  File "/usr/local/lib/python3.8/dist-packages/py4j/java_gateway.py", line 1038, in send_command
    response = connection.send_command(command)
  File "/usr/local/lib/python3.8/dist-packages/py4j/java_gateway.py", line 1228, in send_command
    raise Py4JNetworkError(
py4j.protocol.Py4JNetworkError: Error while receiving
